LAST SEEN   TYPE      REASON                 OBJECT                                           MESSAGE
56m         Normal    Killing                pod/load-generator-worker-cdc7df7c5-5mdlq        Stopping container load-generator-worker
56m         Normal    ScalingReplicaSet      deployment/load-generator-worker                 Scaled down replica set load-generator-worker-cdc7df7c5 from 3 to 1
56m         Normal    SuccessfulRescale      horizontalpodautoscaler/load-generator-worker    New size: 1; reason: All metrics below target
56m         Normal    SuccessfulDelete       replicaset/load-generator-worker-cdc7df7c5       Deleted pod: load-generator-worker-cdc7df7c5-5mdlq
56m         Normal    SuccessfulDelete       replicaset/load-generator-worker-cdc7df7c5       Deleted pod: load-generator-worker-cdc7df7c5-c5df6
56m         Normal    Killing                pod/load-generator-worker-cdc7df7c5-c5df6        Stopping container load-generator-worker
29m         Normal    Scheduled              pod/load-generator-worker-cdc7df7c5-8zbbt        Successfully assigned techx-corp-prod/load-generator-worker-cdc7df7c5-8zbbt to ip-10-0-26-151.ec2.internal
29m         Normal    ScalingReplicaSet      deployment/load-generator-worker                 Scaled up replica set load-generator-worker-cdc7df7c5 from 1 to 3
29m         Normal    Scheduled              pod/load-generator-worker-cdc7df7c5-25ggg        Successfully assigned techx-corp-prod/load-generator-worker-cdc7df7c5-25ggg to ip-10-0-26-151.ec2.internal
29m         Normal    SuccessfulRescale      horizontalpodautoscaler/load-generator-worker    New size: 3; reason: cpu resource utilization (percentage of request) above target
29m         Normal    SuccessfulCreate       replicaset/load-generator-worker-cdc7df7c5       Created pod: load-generator-worker-cdc7df7c5-8zbbt
29m         Normal    SuccessfulCreate       replicaset/load-generator-worker-cdc7df7c5       Created pod: load-generator-worker-cdc7df7c5-25ggg
29m         Normal    Pulled                 pod/load-generator-worker-cdc7df7c5-8zbbt        Container image "493499579600.dkr.ecr.us-east-1.amazonaws.com/techx-prod-corp/load-generator:sha-fa6cb8f" already present on machine and can be accessed by the pod
29m         Normal    Pulled                 pod/load-generator-worker-cdc7df7c5-25ggg        Container image "493499579600.dkr.ecr.us-east-1.amazonaws.com/techx-prod-corp/load-generator:sha-fa6cb8f" already present on machine and can be accessed by the pod
29m         Normal    Created                pod/load-generator-worker-cdc7df7c5-25ggg        Container created
29m         Normal    Started                pod/load-generator-worker-cdc7df7c5-25ggg        Container started
29m         Normal    Started                pod/load-generator-worker-cdc7df7c5-8zbbt        Container started
29m         Normal    Created                pod/load-generator-worker-cdc7df7c5-8zbbt        Container created
28m         Normal    Created                pod/checkout-5f59884d8-cp6zh                     Container created
28m         Normal    SuccessfulRescale      horizontalpodautoscaler/checkout                 New size: 3; reason: cpu resource utilization (percentage of request) above target
28m         Normal    ScalingReplicaSet      deployment/checkout                              Scaled up replica set checkout-5f59884d8 from 2 to 3
28m         Normal    Scheduled              pod/checkout-5f59884d8-cp6zh                     Successfully assigned techx-corp-prod/checkout-5f59884d8-cp6zh to ip-10-0-36-190.ec2.internal
28m         Normal    Pulled                 pod/checkout-5f59884d8-cp6zh                     Container image "493499579600.dkr.ecr.us-east-1.amazonaws.com/techx-prod-corp/checkout:sha-fa6cb8f" already present on machine and can be accessed by the pod
28m         Normal    Started                pod/checkout-5f59884d8-cp6zh                     Container started
28m         Normal    SuccessfulCreate       replicaset/checkout-5f59884d8                    Created pod: checkout-5f59884d8-cp6zh
28m         Normal    SuccessfulCreate       job/runtime-hardening-inventory-29742110         Created pod: runtime-hardening-inventory-29742110-f256j
28m         Normal    SuccessfulCreate       cronjob/runtime-hardening-inventory              Created job runtime-hardening-inventory-29742110
28m         Normal    Scheduled              pod/runtime-hardening-inventory-29742110-f256j   Successfully assigned techx-corp-prod/runtime-hardening-inventory-29742110-f256j to ip-10-0-36-4.ec2.internal
28m         Normal    Pulling                pod/runtime-hardening-inventory-29742110-f256j   Pulling image "public.ecr.aws/docker/library/python:3.13.5-alpine3.22"
28m         Normal    Pulled                 pod/runtime-hardening-inventory-29742110-f256j   Successfully pulled image "public.ecr.aws/docker/library/python:3.13.5-alpine3.22" in 1.682s (1.682s including waiting). Image size: 17152616 bytes.
28m         Normal    SuccessfulCreate       replicaset/load-generator-worker-cdc7df7c5       Created pod: load-generator-worker-cdc7df7c5-78d9m
28m         Normal    SuccessfulRescale      horizontalpodautoscaler/load-generator-worker    New size: 5; reason: cpu resource utilization (percentage of request) above target
28m         Normal    Scheduled              pod/load-generator-worker-cdc7df7c5-78d9m        Successfully assigned techx-corp-prod/load-generator-worker-cdc7df7c5-78d9m to ip-10-0-26-151.ec2.internal
28m         Normal    Created                pod/runtime-hardening-inventory-29742110-f256j   Container created
28m         Normal    Started                pod/runtime-hardening-inventory-29742110-f256j   Container started
28m         Normal    Scheduled              pod/load-generator-worker-cdc7df7c5-9qnsc        Successfully assigned techx-corp-prod/load-generator-worker-cdc7df7c5-9qnsc to ip-10-0-26-151.ec2.internal
28m         Normal    ScalingReplicaSet      deployment/load-generator-worker                 Scaled up replica set load-generator-worker-cdc7df7c5 from 3 to 5
28m         Normal    SuccessfulCreate       replicaset/load-generator-worker-cdc7df7c5       Created pod: load-generator-worker-cdc7df7c5-9qnsc
28m         Normal    Started                pod/load-generator-worker-cdc7df7c5-9qnsc        Container started
28m         Normal    Pulled                 pod/load-generator-worker-cdc7df7c5-9qnsc        Container image "493499579600.dkr.ecr.us-east-1.amazonaws.com/techx-prod-corp/load-generator:sha-fa6cb8f" already present on machine and can be accessed by the pod
28m         Normal    Started                pod/load-generator-worker-cdc7df7c5-78d9m        Container started
28m         Normal    Created                pod/load-generator-worker-cdc7df7c5-9qnsc        Container created
28m         Normal    Created                pod/load-generator-worker-cdc7df7c5-78d9m        Container created
28m         Normal    Pulled                 pod/load-generator-worker-cdc7df7c5-78d9m        Container image "493499579600.dkr.ecr.us-east-1.amazonaws.com/techx-prod-corp/load-generator:sha-fa6cb8f" already present on machine and can be accessed by the pod
28m         Normal    ScalingReplicaSet      deployment/checkout                              Scaled up replica set checkout-5f59884d8 from 3 to 4
28m         Warning   FailedScheduling       pod/checkout-5f59884d8-c2dbn                     0/6 nodes are available: 1 node(s) didn't satisfy existing pods anti-affinity rules, 2 node(s) didn't match Pod's node affinity/selector, 3 node(s) didn't match pod topology spread constraints. no new claims to deallocate, preemption: 0/6 nodes are available: 2 Preemption is not helpful for scheduling, 4 No preemption victims found for incoming pod.
28m         Normal    SuccessfulRescale      horizontalpodautoscaler/checkout                 New size: 4; reason: cpu resource utilization (percentage of request) above target
28m         Normal    SuccessfulCreate       replicaset/checkout-5f59884d8                    Created pod: checkout-5f59884d8-c2dbn
28m         Normal    SawCompletedJob        cronjob/runtime-hardening-inventory              Saw completed job: runtime-hardening-inventory-29742110, condition: Failed
28m         Normal    Nominated              pod/checkout-5f59884d8-c2dbn                     Pod should schedule on: nodeclaim/stateless-spot-mcwmq
28m         Warning   BackoffLimitExceeded   job/runtime-hardening-inventory-29742110         Job has reached the specified backoff limit
28m         Normal    NotTriggerScaleUp      pod/checkout-5f59884d8-c2dbn                     pod didn't trigger scale-up: 2 node(s) didn't match Pod's node affinity/selector
28m         Normal    ScalingReplicaSet      deployment/cart                                  Scaled up replica set cart-6cbfb749cf from 2 to 3
28m         Normal    SuccessfulRescale      horizontalpodautoscaler/cart                     New size: 3; reason: cpu resource utilization (percentage of request) above target
28m         Normal    SuccessfulCreate       replicaset/cart-6cbfb749cf                       Created pod: cart-6cbfb749cf-bw56q
28m         Normal    Scheduled              pod/cart-6cbfb749cf-bw56q                        Successfully assigned techx-corp-prod/cart-6cbfb749cf-bw56q to ip-10-0-36-190.ec2.internal
28m         Normal    Created                pod/cart-6cbfb749cf-bw56q                        Container created
28m         Normal    Started                pod/cart-6cbfb749cf-bw56q                        Container started
28m         Normal    Pulling                pod/cart-6cbfb749cf-bw56q                        Pulling image "busybox:1.37.0"
28m         Normal    Pulled                 pod/cart-6cbfb749cf-bw56q                        Successfully pulled image "busybox:1.37.0" in 145ms (145ms including waiting). Image size: 1911349 bytes.
28m         Normal    Created                pod/cart-6cbfb749cf-bw56q                        Container created
28m         Normal    Started                pod/cart-6cbfb749cf-bw56q                        Container started
28m         Normal    Pulled                 pod/cart-6cbfb749cf-bw56q                        Container image "493499579600.dkr.ecr.us-east-1.amazonaws.com/techx-prod-corp/cart:sha-fa6cb8f" already present on machine and can be accessed by the pod
28m         Normal    SuccessfulCreate       replicaset/frontend-75c8585d46                   Created pod: frontend-75c8585d46-f4jh8
28m         Normal    SuccessfulRescale      horizontalpodautoscaler/frontend                 New size: 5; reason: cpu resource utilization (percentage of request) above target
28m         Normal    ScalingReplicaSet      deployment/frontend                              Scaled up replica set frontend-75c8585d46 from 3 to 5
28m         Warning   FailedScheduling       pod/frontend-75c8585d46-f4v4c                    0/6 nodes are available: 1 node(s) didn't satisfy existing pods anti-affinity rules, 2 node(s) didn't match Pod's node affinity/selector, 3 node(s) didn't match pod topology spread constraints. no new claims to deallocate, preemption: 0/6 nodes are available: 2 Preemption is not helpful for scheduling, 4 No preemption victims found for incoming pod.
28m         Warning   FailedScheduling       pod/frontend-75c8585d46-f4jh8                    0/6 nodes are available: 1 node(s) didn't satisfy existing pods anti-affinity rules, 2 node(s) didn't match Pod's node affinity/selector, 3 node(s) didn't match pod topology spread constraints. no new claims to deallocate, preemption: 0/6 nodes are available: 2 Preemption is not helpful for scheduling, 4 No preemption victims found for incoming pod.
28m         Normal    SuccessfulCreate       replicaset/frontend-75c8585d46                   Created pod: frontend-75c8585d46-f4v4c
28m         Normal    Nominated              pod/frontend-75c8585d46-f4v4c                    Pod should schedule on: nodeclaim/stateless-spot-mcwmq
28m         Normal    Nominated              pod/frontend-75c8585d46-f4jh8                    Pod should schedule on: nodeclaim/stateless-spot-57rr2
28m         Normal    NotTriggerScaleUp      pod/frontend-75c8585d46-f4jh8                    pod didn't trigger scale-up: 2 node(s) didn't match Pod's node affinity/selector
28m         Normal    NotTriggerScaleUp      pod/frontend-75c8585d46-f4v4c                    pod didn't trigger scale-up: 2 node(s) didn't match Pod's node affinity/selector
28m         Normal    ScalingReplicaSet      deployment/cart                                  Scaled up replica set cart-6cbfb749cf from 3 to 4
28m         Normal    SuccessfulRescale      horizontalpodautoscaler/cart                     New size: 4; reason: cpu resource utilization (percentage of request) above target
28m         Warning   FailedScheduling       pod/cart-6cbfb749cf-ncznm                        0/6 nodes are available: 1 node(s) didn't satisfy existing pods anti-affinity rules, 2 node(s) didn't match Pod's node affinity/selector, 3 node(s) didn't match pod topology spread constraints. no new claims to deallocate, preemption: 0/6 nodes are available: 2 Preemption is not helpful for scheduling, 4 No preemption victims found for incoming pod.
28m         Normal    SuccessfulCreate       replicaset/cart-6cbfb749cf                       Created pod: cart-6cbfb749cf-ncznm
28m         Normal    Nominated              pod/cart-6cbfb749cf-ncznm                        Pod should schedule on: nodeclaim/stateless-spot-57rr2
28m         Normal    NotTriggerScaleUp      pod/cart-6cbfb749cf-ncznm                        pod didn't trigger scale-up: 2 node(s) didn't match Pod's node affinity/selector
28m         Warning   FailedScheduling       pod/frontend-75c8585d46-f4v4c                    0/7 nodes are available: 1 node(s) didn't satisfy existing pods anti-affinity rules, 1 node(s) had untolerated taint(s), 2 node(s) didn't match Pod's node affinity/selector, 3 node(s) didn't match pod topology spread constraints. no new claims to deallocate, preemption: 0/7 nodes are available: 3 Preemption is not helpful for scheduling, 4 No preemption victims found for incoming pod.
28m         Warning   FailedScheduling       pod/checkout-5f59884d8-c2dbn                     0/7 nodes are available: 1 node(s) didn't satisfy existing pods anti-affinity rules, 1 node(s) had untolerated taint(s), 2 node(s) didn't match Pod's node affinity/selector, 3 node(s) didn't match pod topology spread constraints. no new claims to deallocate, preemption: 0/7 nodes are available: 3 Preemption is not helpful for scheduling, 4 No preemption victims found for incoming pod.
28m         Warning   FailedScheduling       pod/cart-6cbfb749cf-ncznm                        0/7 nodes are available: 1 node(s) didn't satisfy existing pods anti-affinity rules, 1 node(s) had untolerated taint(s), 2 node(s) didn't match Pod's node affinity/selector, 3 node(s) didn't match pod topology spread constraints. no new claims to deallocate, preemption: 0/7 nodes are available: 3 Preemption is not helpful for scheduling, 4 No preemption victims found for incoming pod.
28m         Warning   FailedScheduling       pod/frontend-75c8585d46-f4jh8                    0/7 nodes are available: 1 node(s) didn't satisfy existing pods anti-affinity rules, 1 node(s) had untolerated taint(s), 2 node(s) didn't match Pod's node affinity/selector, 3 node(s) didn't match pod topology spread constraints. no new claims to deallocate, preemption: 0/7 nodes are available: 3 Preemption is not helpful for scheduling, 4 No preemption victims found for incoming pod.
27m         Normal    ScalingReplicaSet      deployment/checkout                              Scaled up replica set checkout-5f59884d8 from 4 to 5
27m         Normal    SuccessfulRescale      horizontalpodautoscaler/checkout                 New size: 5; reason: cpu resource utilization (percentage of request) above target
27m         Normal    SuccessfulCreate       replicaset/checkout-5f59884d8                    Created pod: checkout-5f59884d8-2wqb9
27m         Normal    Nominated              pod/checkout-5f59884d8-2wqb9                     Pod should schedule on: nodeclaim/stateless-spot-57rr2, node/ip-10-0-22-61.ec2.internal
27m         Normal    NotTriggerScaleUp      pod/checkout-5f59884d8-2wqb9                     pod didn't trigger scale-up: 2 node(s) didn't match Pod's node affinity/selector
27m         Warning   FailedScheduling       pod/frontend-75c8585d46-f4v4c                    0/8 nodes are available: 1 node(s) didn't satisfy existing pods anti-affinity rules, 1 node(s) had untolerated taint(s), 2 node(s) didn't match Pod's node affinity/selector, 4 node(s) didn't match pod topology spread constraints. no new claims to deallocate, preemption: 0/8 nodes are available: 3 Preemption is not helpful for scheduling, 5 No preemption victims found for incoming pod.
27m         Warning   FailedScheduling       pod/cart-6cbfb749cf-ncznm                        0/8 nodes are available: 1 node(s) didn't satisfy existing pods anti-affinity rules, 2 node(s) didn't match Pod's node affinity/selector, 2 node(s) had untolerated taint(s), 3 node(s) didn't match pod topology spread constraints. no new claims to deallocate, preemption: 0/8 nodes are available: 4 No preemption victims found for incoming pod, 4 Preemption is not helpful for scheduling.
27m         Warning   FailedScheduling       pod/frontend-75c8585d46-f4jh8                    0/8 nodes are available: 1 node(s) didn't satisfy existing pods anti-affinity rules, 2 node(s) didn't match Pod's node affinity/selector, 2 node(s) had untolerated taint(s), 3 node(s) didn't match pod topology spread constraints. no new claims to deallocate, preemption: 0/8 nodes are available: 4 No preemption victims found for incoming pod, 4 Preemption is not helpful for scheduling.
27m         Normal    Scheduled              pod/checkout-5f59884d8-2wqb9                     Successfully assigned techx-corp-prod/checkout-5f59884d8-2wqb9 to ip-10-0-16-230.ec2.internal
27m         Normal    Scheduled              pod/frontend-75c8585d46-f4jh8                    Successfully assigned techx-corp-prod/frontend-75c8585d46-f4jh8 to ip-10-0-16-230.ec2.internal
27m         Normal    Scheduled              pod/cart-6cbfb749cf-ncznm                        Successfully assigned techx-corp-prod/cart-6cbfb749cf-ncznm to ip-10-0-16-230.ec2.internal
27m         Warning   FailedScheduling       pod/checkout-5f59884d8-c2dbn                     0/8 nodes are available: 1 node(s) didn't satisfy existing pods anti-affinity rules, 2 node(s) didn't match Pod's node affinity/selector, 2 node(s) had untolerated taint(s), 3 node(s) didn't match pod topology spread constraints. no new claims to deallocate, preemption: 0/8 nodes are available: 4 No preemption victims found for incoming pod, 4 Preemption is not helpful for scheduling.
27m         Warning   FailedScheduling       pod/frontend-75c8585d46-f4v4c                    0/8 nodes are available: 1 node(s) didn't satisfy existing pods anti-affinity rules, 2 node(s) didn't match Pod's node affinity/selector, 2 node(s) had untolerated taint(s), 3 node(s) didn't match pod topology spread constraints. no new claims to deallocate, preemption: 0/8 nodes are available: 4 No preemption victims found for incoming pod, 4 Preemption is not helpful for scheduling.
27m         Warning   FailedScheduling       pod/checkout-5f59884d8-c2dbn                     0/8 nodes are available: 1 node(s) didn't satisfy existing pods anti-affinity rules, 1 node(s) had untolerated taint(s), 2 node(s) didn't match Pod's node affinity/selector, 4 node(s) didn't match pod topology spread constraints. no new claims to deallocate, preemption: 0/8 nodes are available: 3 Preemption is not helpful for scheduling, 5 No preemption victims found for incoming pod.
27m         Normal    SuccessfulCreate       daemonset/otel-collector-agent                   Created pod: otel-collector-agent-qwlh9
27m         Normal    Scheduled              pod/otel-collector-agent-qwlh9                   Successfully assigned techx-corp-prod/otel-collector-agent-qwlh9 to ip-10-0-16-230.ec2.internal
27m         Warning   FailedScheduling       pod/checkout-5f59884d8-2wqb9                     0/8 nodes are available: 1 node(s) didn't satisfy existing pods anti-affinity rules, 2 node(s) didn't match Pod's node affinity/selector, 2 node(s) had untolerated taint(s), 3 node(s) didn't match pod topology spread constraints. no new claims to deallocate, preemption: 0/8 nodes are available: 4 No preemption victims found for incoming pod, 4 Preemption is not helpful for scheduling.
27m         Normal    Pulling                pod/otel-collector-agent-qwlh9                   Pulling image "otel/opentelemetry-collector-contrib:0.151.0"
27m         Normal    Pulling                pod/cart-6cbfb749cf-ncznm                        Pulling image "busybox:1.37.0"
27m         Normal    Pulling                pod/frontend-75c8585d46-f4jh8                    Pulling image "493499579600.dkr.ecr.us-east-1.amazonaws.com/techx-prod-corp/frontend:sha-fa6cb8f"
27m         Normal    Pulling                pod/checkout-5f59884d8-2wqb9                     Pulling image "493499579600.dkr.ecr.us-east-1.amazonaws.com/techx-prod-corp/checkout:sha-fa6cb8f"
27m         Normal    Created                pod/cart-6cbfb749cf-ncznm                        Container created
27m         Normal    Pulled                 pod/cart-6cbfb749cf-ncznm                        Successfully pulled image "busybox:1.37.0" in 2.086s (2.086s including waiting). Image size: 1911349 bytes.
27m         Normal    Started                pod/cart-6cbfb749cf-ncznm                        Container started
27m         Normal    SuccessfulCreate       daemonset/otel-collector-agent                   Created pod: otel-collector-agent-mxjcv
27m         Normal    Scheduled              pod/frontend-75c8585d46-f4v4c                    Successfully assigned techx-corp-prod/frontend-75c8585d46-f4v4c to ip-10-0-22-61.ec2.internal
27m         Normal    Scheduled              pod/checkout-5f59884d8-c2dbn                     Successfully assigned techx-corp-prod/checkout-5f59884d8-c2dbn to ip-10-0-22-61.ec2.internal
27m         Normal    Scheduled              pod/otel-collector-agent-mxjcv                   Successfully assigned techx-corp-prod/otel-collector-agent-mxjcv to ip-10-0-22-61.ec2.internal
27m         Normal    Pulling                pod/otel-collector-agent-mxjcv                   Pulling image "otel/opentelemetry-collector-contrib:0.151.0"
27m         Normal    Pulling                pod/checkout-5f59884d8-c2dbn                     Pulling image "493499579600.dkr.ecr.us-east-1.amazonaws.com/techx-prod-corp/checkout:sha-fa6cb8f"
27m         Normal    TaintManagerEviction   pod/checkout-5f59884d8-2wqb9                     Cancelling deletion of Pod techx-corp-prod/checkout-5f59884d8-2wqb9
27m         Normal    TaintManagerEviction   pod/checkout-5f59884d8-c2dbn                     Cancelling deletion of Pod techx-corp-prod/checkout-5f59884d8-c2dbn
27m         Normal    TaintManagerEviction   pod/frontend-75c8585d46-f4jh8                    Cancelling deletion of Pod techx-corp-prod/frontend-75c8585d46-f4jh8
27m         Normal    TaintManagerEviction   pod/cart-6cbfb749cf-ncznm                        Cancelling deletion of Pod techx-corp-prod/cart-6cbfb749cf-ncznm
27m         Normal    Pulling                pod/frontend-75c8585d46-f4v4c                    Pulling image "493499579600.dkr.ecr.us-east-1.amazonaws.com/techx-prod-corp/frontend:sha-fa6cb8f"
27m         Normal    TaintManagerEviction   pod/frontend-75c8585d46-f4v4c                    Cancelling deletion of Pod techx-corp-prod/frontend-75c8585d46-f4v4c
27m         Normal    Pulled                 pod/checkout-5f59884d8-c2dbn                     Successfully pulled image "493499579600.dkr.ecr.us-east-1.amazonaws.com/techx-prod-corp/checkout:sha-fa6cb8f" in 1.536s (1.536s including waiting). Image size: 9514321 bytes.
27m         Normal    Created                pod/checkout-5f59884d8-c2dbn                     Container created
27m         Normal    Started                pod/checkout-5f59884d8-c2dbn                     Container started
27m         Normal    Pulled                 pod/checkout-5f59884d8-2wqb9                     Successfully pulled image "493499579600.dkr.ecr.us-east-1.amazonaws.com/techx-prod-corp/checkout:sha-fa6cb8f" in 7.955s (7.955s including waiting). Image size: 9514321 bytes.
27m         Normal    Started                pod/checkout-5f59884d8-2wqb9                     Container started
27m         Normal    Created                pod/checkout-5f59884d8-2wqb9                     Container created
27m         Normal    Pulling                pod/cart-6cbfb749cf-ncznm                        Pulling image "493499579600.dkr.ecr.us-east-1.amazonaws.com/techx-prod-corp/cart:sha-fa6cb8f"
27m         Normal    Pulled                 pod/otel-collector-agent-qwlh9                   Successfully pulled image "otel/opentelemetry-collector-contrib:0.151.0" in 9.531s (9.531s including waiting). Image size: 88803327 bytes.
27m         Normal    Created                pod/otel-collector-agent-qwlh9                   Container created
27m         Normal    Started                pod/otel-collector-agent-qwlh9                   Container started
27m         Normal    Pulled                 pod/cart-6cbfb749cf-ncznm                        Successfully pulled image "493499579600.dkr.ecr.us-east-1.amazonaws.com/techx-prod-corp/cart:sha-fa6cb8f" in 3.171s (3.171s including waiting). Image size: 50820594 bytes.
27m         Normal    Created                pod/otel-collector-agent-mxjcv                   Container created
27m         Normal    Pulled                 pod/otel-collector-agent-mxjcv                   Successfully pulled image "otel/opentelemetry-collector-contrib:0.151.0" in 6.344s (6.344s including waiting). Image size: 88803327 bytes.
27m         Normal    Started                pod/otel-collector-agent-mxjcv                   Container started
27m         Normal    Started                pod/cart-6cbfb749cf-ncznm                        Container started
27m         Normal    Created                pod/cart-6cbfb749cf-ncznm                        Container created
27m         Normal    Created                pod/frontend-75c8585d46-f4v4c                    Container created
27m         Normal    Started                pod/frontend-75c8585d46-f4v4c                    Container started
27m         Normal    Pulled                 pod/frontend-75c8585d46-f4v4c                    Successfully pulled image "493499579600.dkr.ecr.us-east-1.amazonaws.com/techx-prod-corp/frontend:sha-fa6cb8f" in 11.704s (11.704s including waiting). Image size: 213499853 bytes.
27m         Normal    Started                pod/frontend-75c8585d46-f4jh8                    Container started
27m         Normal    Created                pod/frontend-75c8585d46-f4jh8                    Container created
27m         Warning   Unhealthy              pod/cart-6cbfb749cf-ncznm                        Liveness probe failed: dial tcp 10.0.26.164:8080: connect: connection refused
27m         Warning   Unhealthy              pod/frontend-75c8585d46-f4v4c                    Readiness probe failed: Get "http://10.0.22.67:8080/": dial tcp 10.0.22.67:8080: connect: connection refused
27m         Normal    Pulled                 pod/frontend-75c8585d46-f4jh8                    Successfully pulled image "493499579600.dkr.ecr.us-east-1.amazonaws.com/techx-prod-corp/frontend:sha-fa6cb8f" in 15.872s (15.872s including waiting). Image size: 213499853 bytes.
27m         Warning   Unhealthy              pod/cart-6cbfb749cf-ncznm                        Readiness probe failed: timeout: health rpc did not complete within 3s
26m         Normal    Scheduled              pod/cart-6cbfb749cf-swtk9                        Successfully assigned techx-corp-prod/cart-6cbfb749cf-swtk9 to ip-10-0-22-61.ec2.internal
26m         Normal    SuccessfulRescale      horizontalpodautoscaler/cart                     New size: 5; reason: cpu resource utilization (percentage of request) above target
26m         Normal    SuccessfulCreate       replicaset/cart-6cbfb749cf                       Created pod: cart-6cbfb749cf-swtk9
26m         Normal    ScalingReplicaSet      deployment/cart                                  Scaled up replica set cart-6cbfb749cf from 4 to 5
26m         Normal    Created                pod/cart-6cbfb749cf-swtk9                        Container created
26m         Normal    Pulled                 pod/cart-6cbfb749cf-swtk9                        Successfully pulled image "busybox:1.37.0" in 573ms (573ms including waiting). Image size: 1911349 bytes.
26m         Normal    Pulling                pod/cart-6cbfb749cf-swtk9                        Pulling image "busybox:1.37.0"
26m         Normal    Started                pod/cart-6cbfb749cf-swtk9                        Container started
26m         Normal    Pulling                pod/cart-6cbfb749cf-swtk9                        Pulling image "493499579600.dkr.ecr.us-east-1.amazonaws.com/techx-prod-corp/cart:sha-fa6cb8f"
26m         Normal    Created                pod/cart-6cbfb749cf-swtk9                        Container created
26m         Normal    Started                pod/cart-6cbfb749cf-swtk9                        Container started
26m         Normal    Pulled                 pod/cart-6cbfb749cf-swtk9                        Successfully pulled image "493499579600.dkr.ecr.us-east-1.amazonaws.com/techx-prod-corp/cart:sha-fa6cb8f" in 1.785s (1.785s including waiting). Image size: 50820594 bytes.
26m         Warning   Unhealthy              pod/cart-6cbfb749cf-swtk9                        Readiness probe failed: timeout: failed to connect service "10.0.22.68:8080" within 3s: context deadline exceeded
26m         Warning   Unhealthy              pod/cart-6cbfb749cf-swtk9                        Readiness probe failed: timeout: health rpc did not complete within 3s
26m         Normal    SuccessfulRescale      horizontalpodautoscaler/cart                     New size: 6; reason: cpu resource utilization (percentage of request) above target
26m         Normal    SuccessfulCreate       replicaset/cart-6cbfb749cf                       Created pod: cart-6cbfb749cf-99stt
26m         Warning   FailedScheduling       pod/cart-6cbfb749cf-99stt                        0/8 nodes are available: 2 node(s) didn't match Pod's node affinity/selector, 6 node(s) didn't match pod topology spread constraints. no new claims to deallocate, preemption: 0/8 nodes are available: 2 Preemption is not helpful for scheduling, 6 No preemption victims found for incoming pod.
26m         Normal    ScalingReplicaSet      deployment/cart                                  Scaled up replica set cart-6cbfb749cf from 5 to 6
26m         Normal    Nominated              pod/cart-6cbfb749cf-99stt                        Pod should schedule on: nodeclaim/stateless-spot-qsbf2
26m         Normal    NotTriggerScaleUp      pod/cart-6cbfb749cf-99stt                        pod didn't trigger scale-up: 2 node(s) didn't match Pod's node affinity/selector
26m         Normal    ScalingReplicaSet      deployment/cart                                  Scaled up replica set cart-6cbfb749cf from 6 to 7
26m         Normal    SuccessfulCreate       replicaset/cart-6cbfb749cf                       Created pod: cart-6cbfb749cf-92hdl
26m         Warning   FailedScheduling       pod/cart-6cbfb749cf-92hdl                        0/8 nodes are available: 2 node(s) didn't match Pod's node affinity/selector, 6 node(s) didn't match pod topology spread constraints. no new claims to deallocate, preemption: 0/8 nodes are available: 2 Preemption is not helpful for scheduling, 6 No preemption victims found for incoming pod.
26m         Normal    SuccessfulRescale      horizontalpodautoscaler/cart                     New size: 7; reason: cpu resource utilization (percentage of request) above target
26m         Normal    Nominated              pod/cart-6cbfb749cf-92hdl                        Pod should schedule on: nodeclaim/stateless-spot-9g7sv
26m         Normal    NotTriggerScaleUp      pod/cart-6cbfb749cf-92hdl                        pod didn't trigger scale-up: 2 node(s) didn't match Pod's node affinity/selector
25m         Warning   FailedScheduling       pod/cart-6cbfb749cf-99stt                        0/9 nodes are available: 1 node(s) had untolerated taint(s), 2 node(s) didn't match Pod's node affinity/selector, 6 node(s) didn't match pod topology spread constraints. no new claims to deallocate, preemption: 0/9 nodes are available: 3 Preemption is not helpful for scheduling, 6 No preemption victims found for incoming pod.
25m         Warning   FailedScheduling       pod/cart-6cbfb749cf-92hdl                        0/9 nodes are available: 1 node(s) had untolerated taint(s), 2 node(s) didn't match Pod's node affinity/selector, 6 node(s) didn't match pod topology spread constraints. no new claims to deallocate, preemption: 0/9 nodes are available: 3 Preemption is not helpful for scheduling, 6 No preemption victims found for incoming pod.
25m         Normal    Scheduled              pod/otel-collector-agent-nrrj7                   Successfully assigned techx-corp-prod/otel-collector-agent-nrrj7 to ip-10-0-37-197.ec2.internal
25m         Normal    Scheduled              pod/cart-6cbfb749cf-99stt                        Successfully assigned techx-corp-prod/cart-6cbfb749cf-99stt to ip-10-0-37-197.ec2.internal
25m         Normal    SuccessfulCreate       daemonset/otel-collector-agent                   Created pod: otel-collector-agent-nrrj7
25m         Normal    Pulling                pod/otel-collector-agent-nrrj7                   Pulling image "otel/opentelemetry-collector-contrib:0.151.0"
25m         Normal    Pulling                pod/cart-6cbfb749cf-99stt                        Pulling image "busybox:1.37.0"
25m         Normal    Pulled                 pod/cart-6cbfb749cf-99stt                        Successfully pulled image "busybox:1.37.0" in 826ms (826ms including waiting). Image size: 1911349 bytes.
25m         Normal    Started                pod/cart-6cbfb749cf-99stt                        Container started
25m         Normal    Created                pod/cart-6cbfb749cf-99stt                        Container created
25m         Warning   FailedScheduling       pod/cart-6cbfb749cf-92hdl                        0/9 nodes are available: 1 node(s) didn't satisfy existing pods anti-affinity rules, 2 node(s) didn't match Pod's node affinity/selector, 6 node(s) didn't match pod topology spread constraints. no new claims to deallocate, preemption: 0/9 nodes are available: 2 Preemption is not helpful for scheduling, 7 No preemption victims found for incoming pod.
25m         Normal    TaintManagerEviction   pod/cart-6cbfb749cf-99stt                        Cancelling deletion of Pod techx-corp-prod/cart-6cbfb749cf-99stt
25m         Normal    Pulling                pod/cart-6cbfb749cf-99stt                        Pulling image "493499579600.dkr.ecr.us-east-1.amazonaws.com/techx-prod-corp/cart:sha-fa6cb8f"
25m         Normal    Started                pod/otel-collector-agent-nrrj7                   Container started
25m         Normal    Created                pod/otel-collector-agent-nrrj7                   Container created
25m         Normal    Pulled                 pod/otel-collector-agent-nrrj7                   Successfully pulled image "otel/opentelemetry-collector-contrib:0.151.0" in 4.722s (4.722s including waiting). Image size: 88803327 bytes.
25m         Normal    Started                pod/cart-6cbfb749cf-99stt                        Container started
25m         Normal    Created                pod/cart-6cbfb749cf-99stt                        Container created
25m         Normal    Pulled                 pod/cart-6cbfb749cf-99stt                        Successfully pulled image "493499579600.dkr.ecr.us-east-1.amazonaws.com/techx-prod-corp/cart:sha-fa6cb8f" in 2.207s (2.207s including waiting). Image size: 50820594 bytes.
25m         Warning   FailedScheduling       pod/cart-6cbfb749cf-92hdl                        0/10 nodes are available: 1 node(s) didn't satisfy existing pods anti-affinity rules, 1 node(s) had untolerated taint(s), 2 node(s) didn't match Pod's node affinity/selector, 6 node(s) didn't match pod topology spread constraints. no new claims to deallocate, preemption: 0/10 nodes are available: 3 Preemption is not helpful for scheduling, 7 No preemption victims found for incoming pod.
25m         Warning   Unhealthy              pod/cart-6cbfb749cf-99stt                        Readiness probe failed: timeout: failed to connect service "10.0.35.81:8080" within 3s: context deadline exceeded
25m         Warning   Unhealthy              pod/cart-6cbfb749cf-99stt                        Liveness probe failed: dial tcp 10.0.35.81:8080: connect: connection refused
25m         Warning   Unhealthy              pod/cart-6cbfb749cf-99stt                        Readiness probe failed: timeout: health rpc did not complete within 3s
25m         Normal    Pulling                pod/cart-6cbfb749cf-92hdl                        Pulling image "busybox:1.37.0"
25m         Normal    SuccessfulCreate       daemonset/otel-collector-agent                   Created pod: otel-collector-agent-k8d2p
25m         Normal    Scheduled              pod/otel-collector-agent-k8d2p                   Successfully assigned techx-corp-prod/otel-collector-agent-k8d2p to ip-10-0-17-103.ec2.internal
25m         Normal    Pulling                pod/otel-collector-agent-k8d2p                   Pulling image "otel/opentelemetry-collector-contrib:0.151.0"
25m         Normal    Scheduled              pod/cart-6cbfb749cf-92hdl                        Successfully assigned techx-corp-prod/cart-6cbfb749cf-92hdl to ip-10-0-17-103.ec2.internal
25m         Normal    TaintManagerEviction   pod/cart-6cbfb749cf-92hdl                        Cancelling deletion of Pod techx-corp-prod/cart-6cbfb749cf-92hdl
25m         Normal    Started                pod/cart-6cbfb749cf-92hdl                        Container started
25m         Normal    Created                pod/cart-6cbfb749cf-92hdl                        Container created
25m         Normal    Pulled                 pod/cart-6cbfb749cf-92hdl                        Successfully pulled image "busybox:1.37.0" in 523ms (523ms including waiting). Image size: 1911349 bytes.
25m         Normal    Pulling                pod/cart-6cbfb749cf-92hdl                        Pulling image "493499579600.dkr.ecr.us-east-1.amazonaws.com/techx-prod-corp/cart:sha-fa6cb8f"
25m         Normal    Started                pod/otel-collector-agent-k8d2p                   Container started
25m         Normal    Created                pod/otel-collector-agent-k8d2p                   Container created
25m         Normal    Pulled                 pod/otel-collector-agent-k8d2p                   Successfully pulled image "otel/opentelemetry-collector-contrib:0.151.0" in 5.823s (5.823s including waiting). Image size: 88803327 bytes.
25m         Normal    Pulled                 pod/cart-6cbfb749cf-92hdl                        Successfully pulled image "493499579600.dkr.ecr.us-east-1.amazonaws.com/techx-prod-corp/cart:sha-fa6cb8f" in 2.721s (2.721s including waiting). Image size: 50820594 bytes.
25m         Normal    Created                pod/cart-6cbfb749cf-92hdl                        Container created
25m         Normal    Started                pod/cart-6cbfb749cf-92hdl                        Container started
25m         Warning   Unhealthy              pod/cart-6cbfb749cf-92hdl                        Readiness probe failed: timeout: failed to connect service "10.0.27.240:8080" within 3s: context deadline exceeded
25m         Warning   Unhealthy              pod/cart-6cbfb749cf-92hdl                        Liveness probe failed: dial tcp 10.0.27.240:8080: connect: connection refused
25m         Warning   Unhealthy              pod/cart-6cbfb749cf-92hdl                        Readiness probe failed: timeout: health rpc did not complete within 3s
24m         Normal    SuccessfulRescale      horizontalpodautoscaler/checkout                 New size: 6; reason: cpu resource utilization (percentage of request) above target
24m         Normal    ScalingReplicaSet      deployment/checkout                              Scaled up replica set checkout-5f59884d8 from 5 to 6
24m         Normal    SuccessfulCreate       replicaset/checkout-5f59884d8                    Created pod: checkout-5f59884d8-8gpz8
24m         Normal    Scheduled              pod/checkout-5f59884d8-8gpz8                     Successfully assigned techx-corp-prod/checkout-5f59884d8-8gpz8 to ip-10-0-37-197.ec2.internal
24m         Normal    Pulling                pod/checkout-5f59884d8-8gpz8                     Pulling image "493499579600.dkr.ecr.us-east-1.amazonaws.com/techx-prod-corp/checkout:sha-fa6cb8f"
24m         Normal    Pulled                 pod/checkout-5f59884d8-8gpz8                     Successfully pulled image "493499579600.dkr.ecr.us-east-1.amazonaws.com/techx-prod-corp/checkout:sha-fa6cb8f" in 1.042s (1.042s including waiting). Image size: 9514321 bytes.
24m         Normal    Started                pod/checkout-5f59884d8-8gpz8                     Container started
24m         Normal    Created                pod/checkout-5f59884d8-8gpz8                     Container created
23m         Normal    ScalingReplicaSet      deployment/cart                                  Scaled up replica set cart-6cbfb749cf from 7 to 9
23m         Warning   FailedScheduling       pod/cart-6cbfb749cf-gfdwh                        0/10 nodes are available: 2 node(s) didn't match Pod's node affinity/selector, 8 node(s) didn't match pod topology spread constraints. no new claims to deallocate, preemption: 0/10 nodes are available: 2 Preemption is not helpful for scheduling, 8 No preemption victims found for incoming pod.
23m         Normal    SuccessfulCreate       replicaset/cart-6cbfb749cf                       Created pod: cart-6cbfb749cf-gfdwh
23m         Warning   FailedScheduling       pod/cart-6cbfb749cf-x88bh                        0/10 nodes are available: 2 node(s) didn't match Pod's node affinity/selector, 8 node(s) didn't match pod topology spread constraints. no new claims to deallocate, preemption: 0/10 nodes are available: 2 Preemption is not helpful for scheduling, 8 No preemption victims found for incoming pod.
23m         Normal    SuccessfulCreate       replicaset/cart-6cbfb749cf                       Created pod: cart-6cbfb749cf-x88bh
23m         Normal    Nominated              pod/cart-6cbfb749cf-x88bh                        Pod should schedule on: nodeclaim/stateless-spot-k9sr8
23m         Normal    Nominated              pod/cart-6cbfb749cf-gfdwh                        Pod should schedule on: nodeclaim/stateless-spot-8nqqg
23m         Normal    NotTriggerScaleUp      pod/cart-6cbfb749cf-gfdwh                        pod didn't trigger scale-up: 2 node(s) didn't match Pod's node affinity/selector
23m         Normal    NotTriggerScaleUp      pod/cart-6cbfb749cf-x88bh                        pod didn't trigger scale-up: 2 node(s) didn't match Pod's node affinity/selector
23m         Normal    SuccessfulCreate       job/runtime-hardening-inventory-29742115         Created pod: runtime-hardening-inventory-29742115-h9bpw
23m         Normal    Scheduled              pod/runtime-hardening-inventory-29742115-h9bpw   Successfully assigned techx-corp-prod/runtime-hardening-inventory-29742115-h9bpw to ip-10-0-36-4.ec2.internal
23m         Normal    Pulled                 pod/runtime-hardening-inventory-29742115-h9bpw   Container image "public.ecr.aws/docker/library/python:3.13.5-alpine3.22" already present on machine and can be accessed by the pod
23m         Normal    Created                pod/runtime-hardening-inventory-29742115-h9bpw   Container created
23m         Normal    SuccessfulCreate       cronjob/runtime-hardening-inventory              Created job runtime-hardening-inventory-29742115
23m         Normal    Started                pod/runtime-hardening-inventory-29742115-h9bpw   Container started
23m         Warning   FailedScheduling       pod/cart-6cbfb749cf-gfdwh                        0/11 nodes are available: 1 node(s) had untolerated taint(s), 2 node(s) didn't match Pod's node affinity/selector, 8 node(s) didn't match pod topology spread constraints. no new claims to deallocate, preemption: 0/11 nodes are available: 3 Preemption is not helpful for scheduling, 8 No preemption victims found for incoming pod.
23m         Warning   FailedScheduling       pod/cart-6cbfb749cf-x88bh                        0/11 nodes are available: 1 node(s) had untolerated taint(s), 2 node(s) didn't match Pod's node affinity/selector, 8 node(s) didn't match pod topology spread constraints. no new claims to deallocate, preemption: 0/11 nodes are available: 3 Preemption is not helpful for scheduling, 8 No preemption victims found for incoming pod.
23m         Warning   FailedScheduling       pod/cart-6cbfb749cf-x88bh                        0/12 nodes are available: 2 node(s) didn't match Pod's node affinity/selector, 2 node(s) had untolerated taint(s), 8 node(s) didn't match pod topology spread constraints. no new claims to deallocate, preemption: 0/12 nodes are available: 4 Preemption is not helpful for scheduling, 8 No preemption victims found for incoming pod.
23m         Warning   FailedScheduling       pod/cart-6cbfb749cf-gfdwh                        0/12 nodes are available: 2 node(s) didn't match Pod's node affinity/selector, 2 node(s) had untolerated taint(s), 8 node(s) didn't match pod topology spread constraints. no new claims to deallocate, preemption: 0/12 nodes are available: 4 Preemption is not helpful for scheduling, 8 No preemption victims found for incoming pod.
23m         Normal    SawCompletedJob        cronjob/runtime-hardening-inventory              Saw completed job: runtime-hardening-inventory-29742115, condition: Failed
23m         Warning   BackoffLimitExceeded   job/runtime-hardening-inventory-29742115         Job has reached the specified backoff limit
23m         Normal    SuccessfulCreate       daemonset/otel-collector-agent                   Created pod: otel-collector-agent-wbrhx
23m         Normal    Scheduled              pod/otel-collector-agent-wbrhx                   Successfully assigned techx-corp-prod/otel-collector-agent-wbrhx to ip-10-0-31-4.ec2.internal
23m         Normal    Pulling                pod/otel-collector-agent-wbrhx                   Pulling image "otel/opentelemetry-collector-contrib:0.151.0"
23m         Normal    SuccessfulCreate       daemonset/otel-collector-agent                   Created pod: otel-collector-agent-6q48k
23m         Warning   FailedScheduling       pod/cart-6cbfb749cf-x88bh                        0/12 nodes are available: 1 node(s) had untolerated taint(s), 2 node(s) didn't match Pod's node affinity/selector, 9 node(s) didn't match pod topology spread constraints. no new claims to deallocate, preemption: 0/12 nodes are available: 3 Preemption is not helpful for scheduling, 9 No preemption victims found for incoming pod.
23m         Normal    Scheduled              pod/cart-6cbfb749cf-x88bh                        Successfully assigned techx-corp-prod/cart-6cbfb749cf-x88bh to ip-10-0-31-4.ec2.internal
23m         Warning   FailedScheduling       pod/cart-6cbfb749cf-gfdwh                        0/12 nodes are available: 1 node(s) had untolerated taint(s), 2 node(s) didn't match Pod's node affinity/selector, 9 node(s) didn't match pod topology spread constraints. no new claims to deallocate, preemption: 0/12 nodes are available: 3 Preemption is not helpful for scheduling, 9 No preemption victims found for incoming pod.
23m         Normal    Scheduled              pod/otel-collector-agent-6q48k                   Successfully assigned techx-corp-prod/otel-collector-agent-6q48k to ip-10-0-40-214.ec2.internal
23m         Normal    Scheduled              pod/cart-6cbfb749cf-gfdwh                        Successfully assigned techx-corp-prod/cart-6cbfb749cf-gfdwh to ip-10-0-40-214.ec2.internal
23m         Normal    Pulled                 pod/cart-6cbfb749cf-gfdwh                        Successfully pulled image "busybox:1.37.0" in 575ms (575ms including waiting). Image size: 1911349 bytes.
23m         Normal    Pulling                pod/cart-6cbfb749cf-x88bh                        Pulling image "busybox:1.37.0"
23m         Normal    Started                pod/cart-6cbfb749cf-gfdwh                        Container started
23m         Normal    Created                pod/cart-6cbfb749cf-gfdwh                        Container created
23m         Normal    Pulling                pod/cart-6cbfb749cf-gfdwh                        Pulling image "busybox:1.37.0"
23m         Normal    Created                pod/cart-6cbfb749cf-x88bh                        Container created
23m         Normal    Pulling                pod/otel-collector-agent-6q48k                   Pulling image "otel/opentelemetry-collector-contrib:0.151.0"
23m         Normal    Pulled                 pod/cart-6cbfb749cf-x88bh                        Successfully pulled image "busybox:1.37.0" in 637ms (637ms including waiting). Image size: 1911349 bytes.
23m         Normal    Pulling                pod/cart-6cbfb749cf-gfdwh                        Pulling image "493499579600.dkr.ecr.us-east-1.amazonaws.com/techx-prod-corp/cart:sha-fa6cb8f"
23m         Normal    Started                pod/cart-6cbfb749cf-x88bh                        Container started
23m         Normal    Killing                pod/load-generator-worker-cdc7df7c5-9qnsc        Stopping container load-generator-worker
23m         Normal    SuccessfulRescale      horizontalpodautoscaler/load-generator-worker    New size: 4; reason: All metrics below target
23m         Normal    SuccessfulDelete       replicaset/load-generator-worker-cdc7df7c5       Deleted pod: load-generator-worker-cdc7df7c5-9qnsc
23m         Normal    ScalingReplicaSet      deployment/load-generator-worker                 Scaled down replica set load-generator-worker-cdc7df7c5 from 5 to 4
23m         Normal    Pulled                 pod/otel-collector-agent-wbrhx                   Successfully pulled image "otel/opentelemetry-collector-contrib:0.151.0" in 5.688s (5.688s including waiting). Image size: 88803327 bytes.
23m         Normal    TaintManagerEviction   pod/cart-6cbfb749cf-gfdwh                        Cancelling deletion of Pod techx-corp-prod/cart-6cbfb749cf-gfdwh
23m         Normal    Created                pod/cart-6cbfb749cf-gfdwh                        Container created
23m         Normal    Created                pod/otel-collector-agent-6q48k                   Container created
23m         Normal    Started                pod/otel-collector-agent-wbrhx                   Container started
23m         Normal    Created                pod/otel-collector-agent-wbrhx                   Container created
23m         Normal    Started                pod/cart-6cbfb749cf-gfdwh                        Container started
23m         Normal    Pulled                 pod/cart-6cbfb749cf-gfdwh                        Successfully pulled image "493499579600.dkr.ecr.us-east-1.amazonaws.com/techx-prod-corp/cart:sha-fa6cb8f" in 3.369s (3.369s including waiting). Image size: 50820594 bytes.
23m         Normal    Started                pod/otel-collector-agent-6q48k                   Container started
23m         Normal    Pulled                 pod/otel-collector-agent-6q48k                   Successfully pulled image "otel/opentelemetry-collector-contrib:0.151.0" in 5.166s (5.166s including waiting). Image size: 88803327 bytes.
23m         Normal    Pulling                pod/cart-6cbfb749cf-x88bh                        Pulling image "493499579600.dkr.ecr.us-east-1.amazonaws.com/techx-prod-corp/cart:sha-fa6cb8f"
23m         Normal    Pulled                 pod/cart-6cbfb749cf-x88bh                        Successfully pulled image "493499579600.dkr.ecr.us-east-1.amazonaws.com/techx-prod-corp/cart:sha-fa6cb8f" in 1.97s (1.97s including waiting). Image size: 50820594 bytes.
23m         Warning   Unhealthy              pod/cart-6cbfb749cf-gfdwh                        Readiness probe failed: timeout: failed to connect service "10.0.37.240:8080" within 3s: context deadline exceeded
23m         Normal    Created                pod/cart-6cbfb749cf-x88bh                        Container created
23m         Normal    Started                pod/cart-6cbfb749cf-x88bh                        Container started
23m         Warning   Unhealthy              pod/cart-6cbfb749cf-x88bh                        Liveness probe failed: dial tcp 10.0.17.34:8080: connect: connection refused
23m         Warning   Unhealthy              pod/cart-6cbfb749cf-x88bh                        Readiness probe failed: timeout: failed to connect service "10.0.17.34:8080" within 3s: context deadline exceeded
23m         Warning   Unhealthy              pod/cart-6cbfb749cf-x88bh                        Readiness probe failed: timeout: health rpc did not complete within 3s
22m         Normal    Killing                pod/frontend-75c8585d46-f4v4c                    Stopping container frontend
22m         Normal    SuccessfulDelete       replicaset/frontend-75c8585d46                   Deleted pod: frontend-75c8585d46-f4v4c
22m         Normal    SuccessfulRescale      horizontalpodautoscaler/frontend                 New size: 4; reason: All metrics below target
22m         Normal    ScalingReplicaSet      deployment/frontend                              Scaled down replica set frontend-75c8585d46 from 5 to 4
19m         Normal    Killing                pod/cart-6cbfb749cf-gfdwh                        Stopping container cart
19m         Normal    SuccessfulDelete       replicaset/cart-6cbfb749cf                       Deleted pod: cart-6cbfb749cf-gfdwh
18m         Normal    ScalingReplicaSet      deployment/cart                                  Scaled down replica set cart-6cbfb749cf from 8 to 7
18m         Normal    SuccessfulRescale      horizontalpodautoscaler/cart                     New size: 7; reason: All metrics below target
18m         Normal    SuccessfulDelete       replicaset/cart-6cbfb749cf                       Deleted pod: cart-6cbfb749cf-x88bh
18m         Normal    Killing                pod/cart-6cbfb749cf-x88bh                        Stopping container cart
18m         Normal    ScalingReplicaSet      deployment/cart                                  Scaled down replica set cart-6cbfb749cf from 7 to 6
18m         Normal    SuccessfulDelete       replicaset/cart-6cbfb749cf                       Deleted pod: cart-6cbfb749cf-99stt
18m         Normal    Killing                pod/cart-6cbfb749cf-99stt                        Stopping container cart
18m         Normal    SuccessfulCreate       cronjob/runtime-hardening-inventory              Created job runtime-hardening-inventory-29742120
18m         Normal    SuccessfulCreate       job/runtime-hardening-inventory-29742120         Created pod: runtime-hardening-inventory-29742120-b7275
18m         Normal    Scheduled              pod/runtime-hardening-inventory-29742120-b7275   Successfully assigned techx-corp-prod/runtime-hardening-inventory-29742120-b7275 to ip-10-0-36-4.ec2.internal
18m         Normal    Started                pod/runtime-hardening-inventory-29742120-b7275   Container started
18m         Normal    Created                pod/runtime-hardening-inventory-29742120-b7275   Container created
18m         Normal    Pulled                 pod/runtime-hardening-inventory-29742120-b7275   Container image "public.ecr.aws/docker/library/python:3.13.5-alpine3.22" already present on machine and can be accessed by the pod
18m         Normal    Evicted                pod/cart-6cbfb749cf-92hdl                        Evicted pod: Underutilized
18m         Normal    Nominated              pod/cart-6cbfb749cf-92hdl                        Pod should schedule on: nodeclaim/stateless-spot-k9sr8, node/ip-10-0-31-4.ec2.internal
18m         Normal    Killing                pod/cart-6cbfb749cf-92hdl                        Stopping container cart
18m         Normal    Pulling                pod/cart-6cbfb749cf-dxs96                        Pulling image "busybox:1.37.0"
18m         Normal    Scheduled              pod/cart-6cbfb749cf-dxs96                        Successfully assigned techx-corp-prod/cart-6cbfb749cf-dxs96 to ip-10-0-40-214.ec2.internal
18m         Normal    SuccessfulCreate       replicaset/cart-6cbfb749cf                       Created pod: cart-6cbfb749cf-dxs96
18m         Normal    Started                pod/cart-6cbfb749cf-dxs96                        Container started
18m         Normal    Pulled                 pod/cart-6cbfb749cf-dxs96                        Container image "493499579600.dkr.ecr.us-east-1.amazonaws.com/techx-prod-corp/cart:sha-fa6cb8f" already present on machine and can be accessed by the pod
18m         Normal    Created                pod/cart-6cbfb749cf-dxs96                        Container created
18m         Normal    Started                pod/cart-6cbfb749cf-dxs96                        Container started
18m         Normal    Pulled                 pod/cart-6cbfb749cf-dxs96                        Successfully pulled image "busybox:1.37.0" in 247ms (247ms including waiting). Image size: 1911349 bytes.
18m         Normal    Created                pod/cart-6cbfb749cf-dxs96                        Container created
18m         Warning   Unhealthy              pod/cart-6cbfb749cf-dxs96                        Readiness probe failed: timeout: failed to connect service "10.0.37.243:8080" within 3s: context deadline exceeded
18m         Normal    SawCompletedJob        cronjob/runtime-hardening-inventory              Saw completed job: runtime-hardening-inventory-29742120, condition: Failed
18m         Warning   BackoffLimitExceeded   job/runtime-hardening-inventory-29742120         Job has reached the specified backoff limit
18m         Normal    Evicted                pod/otel-collector-agent-k8d2p                   Evicted pod: Underutilized
18m         Normal    Killing                pod/otel-collector-agent-k8d2p                   Stopping container opentelemetry-collector
17m         Normal    Nominated              pod/cart-6cbfb749cf-swtk9                        Pod should schedule on: nodeclaim/stateless-spot-k9sr8, node/ip-10-0-31-4.ec2.internal
17m         Normal    Nominated              pod/checkout-5f59884d8-c2dbn                     Pod should schedule on: nodeclaim/stateless-spot-k9sr8, node/ip-10-0-31-4.ec2.internal
17m         Normal    Killing                pod/cart-6cbfb749cf-swtk9                        Stopping container cart
17m         Normal    Scheduled              pod/checkout-5f59884d8-69fnj                     Successfully assigned techx-corp-prod/checkout-5f59884d8-69fnj to ip-10-0-31-4.ec2.internal
17m         Normal    Pulling                pod/cart-6cbfb749cf-d8mm5                        Pulling image "busybox:1.37.0"
17m         Normal    Pulled                 pod/cart-6cbfb749cf-d8mm5                        Successfully pulled image "busybox:1.37.0" in 240ms (240ms including waiting). Image size: 1911349 bytes.
17m         Normal    Evicted                pod/cart-6cbfb749cf-swtk9                        Evicted pod: Underutilized
17m         Normal    SuccessfulCreate       replicaset/checkout-5f59884d8                    Created pod: checkout-5f59884d8-69fnj
17m         Normal    SuccessfulCreate       replicaset/cart-6cbfb749cf                       Created pod: cart-6cbfb749cf-d8mm5
17m         Normal    Evicted                pod/checkout-5f59884d8-c2dbn                     Evicted pod: Underutilized
17m         Normal    Killing                pod/checkout-5f59884d8-c2dbn                     Stopping container checkout
17m         Normal    Scheduled              pod/cart-6cbfb749cf-d8mm5                        Successfully assigned techx-corp-prod/cart-6cbfb749cf-d8mm5 to ip-10-0-31-4.ec2.internal
17m         Normal    Pulling                pod/checkout-5f59884d8-69fnj                     Pulling image "493499579600.dkr.ecr.us-east-1.amazonaws.com/techx-prod-corp/checkout:sha-fa6cb8f"
17m         Normal    Started                pod/cart-6cbfb749cf-d8mm5                        Container started
17m         Normal    Created                pod/cart-6cbfb749cf-d8mm5                        Container created
17m         Normal    Pulled                 pod/cart-6cbfb749cf-d8mm5                        Container image "493499579600.dkr.ecr.us-east-1.amazonaws.com/techx-prod-corp/cart:sha-fa6cb8f" already present on machine and can be accessed by the pod
17m         Normal    Started                pod/cart-6cbfb749cf-d8mm5                        Container started
17m         Normal    Created                pod/cart-6cbfb749cf-d8mm5                        Container created
17m         Normal    Pulled                 pod/checkout-5f59884d8-69fnj                     Successfully pulled image "493499579600.dkr.ecr.us-east-1.amazonaws.com/techx-prod-corp/checkout:sha-fa6cb8f" in 1.21s (1.21s including waiting). Image size: 9514321 bytes.
17m         Normal    Created                pod/checkout-5f59884d8-69fnj                     Container created
17m         Normal    Started                pod/checkout-5f59884d8-69fnj                     Container started
17m         Warning   Unhealthy              pod/cart-6cbfb749cf-d8mm5                        Readiness probe failed: timeout: failed to connect service "10.0.24.192:8080" within 3s: context deadline exceeded
17m         Warning   Unhealthy              pod/cart-6cbfb749cf-d8mm5                        Readiness probe failed: timeout: health rpc did not complete within 3s
17m         Normal    Killing                pod/otel-collector-agent-mxjcv                   Stopping container opentelemetry-collector
17m         Normal    Evicted                pod/otel-collector-agent-mxjcv                   Evicted pod: Underutilized
17m         Normal    Scheduled              pod/currency-54d784bd7b-mjrtn                    Successfully assigned techx-corp-prod/currency-54d784bd7b-mjrtn to ip-10-0-40-214.ec2.internal
17m         Normal    Scheduled              pod/product-reviews-58686f5fd9-qs6jg             Successfully assigned techx-corp-prod/product-reviews-58686f5fd9-qs6jg to ip-10-0-37-197.ec2.internal
17m         Normal    Nominated              pod/email-746cdfc565-s9dpt                       Pod should schedule on: nodeclaim/stateless-spot-bwp68, node/ip-10-0-36-190.ec2.internal
17m         Normal    Nominated              pod/frontend-75c8585d46-7kfzl                    Pod should schedule on: nodeclaim/stateless-spot-qsbf2, node/ip-10-0-37-197.ec2.internal
17m         Normal    Scheduled              pod/cart-6cbfb749cf-zghqz                        Successfully assigned techx-corp-prod/cart-6cbfb749cf-zghqz to ip-10-0-37-197.ec2.internal
17m         Normal    Killing                pod/ad-7998665c4b-btnwx                          Stopping container ad
17m         Normal    Evicted                pod/ad-7998665c4b-btnwx                          Evicted pod: Underutilized
17m         Normal    Scheduled              pod/ad-7998665c4b-g5hc8                          Successfully assigned techx-corp-prod/ad-7998665c4b-g5hc8 to ip-10-0-40-214.ec2.internal
17m         Normal    Killing                pod/shipping-567ccf6f47-lxbdp                    Stopping container shipping
17m         Normal    Nominated              pod/shipping-567ccf6f47-lxbdp                    Pod should schedule on: nodeclaim/stateless-spot-bwp68, node/ip-10-0-36-190.ec2.internal
17m         Normal    Evicted                pod/accounting-69d676466f-f8rm9                  Evicted pod: Underutilized
17m         Normal    Scheduled              pod/shipping-567ccf6f47-jpz6z                    Successfully assigned techx-corp-prod/shipping-567ccf6f47-jpz6z to ip-10-0-40-214.ec2.internal
17m         Normal    Evicted                pod/cart-6cbfb749cf-ft5cb                        Evicted pod: Underutilized
17m         Normal    Evicted                pod/currency-54d784bd7b-s94g8                    Evicted pod: Underutilized
17m         Normal    Scheduled              pod/accounting-69d676466f-6jtpf                  Successfully assigned techx-corp-prod/accounting-69d676466f-6jtpf to ip-10-0-31-4.ec2.internal
17m         Normal    Killing                pod/accounting-69d676466f-f8rm9                  Stopping container accounting
17m         Normal    Nominated              pod/accounting-69d676466f-f8rm9                  Pod should schedule on: nodeclaim/stateless-spot-mcwmq, node/ip-10-0-16-230.ec2.internal
17m         Normal    Scheduled              pod/checkout-5f59884d8-ltz7v                     Successfully assigned techx-corp-prod/checkout-5f59884d8-ltz7v to ip-10-0-40-214.ec2.internal
17m         Normal    SuccessfulCreate       replicaset/frontend-75c8585d46                   Created pod: frontend-75c8585d46-k6927
17m         Normal    Nominated              pod/cart-6cbfb749cf-ft5cb                        Pod should schedule on: nodeclaim/stateless-spot-qsbf2, node/ip-10-0-37-197.ec2.internal
17m         Normal    Killing                pod/frontend-75c8585d46-7kfzl                    Stopping container frontend
17m         Normal    SuccessfulCreate       replicaset/product-reviews-58686f5fd9            Created pod: product-reviews-58686f5fd9-qs6jg
17m         Normal    Killing                pod/email-746cdfc565-s9dpt                       Stopping container email
17m         Normal    Evicted                pod/email-746cdfc565-s9dpt                       Evicted pod: Underutilized
17m         Normal    Killing                pod/currency-54d784bd7b-s94g8                    Stopping container currency
17m         Normal    Nominated              pod/ad-7998665c4b-btnwx                          Pod should schedule on: nodeclaim/stateless-spot-bwp68, node/ip-10-0-36-190.ec2.internal
17m         Normal    Nominated              pod/currency-54d784bd7b-s94g8                    Pod should schedule on: nodeclaim/stateless-spot-bwp68, node/ip-10-0-36-190.ec2.internal
17m         Normal    Scheduled              pod/frontend-75c8585d46-k6927                    Successfully assigned techx-corp-prod/frontend-75c8585d46-k6927 to ip-10-0-40-214.ec2.internal
17m         Normal    SuccessfulCreate       replicaset/accounting-69d676466f                 Created pod: accounting-69d676466f-6jtpf
17m         Normal    Nominated              pod/product-reviews-58686f5fd9-dqgt6             Pod should schedule on: nodeclaim/stateless-spot-bwp68, node/ip-10-0-36-190.ec2.internal
17m         Normal    Killing                pod/product-reviews-58686f5fd9-dqgt6             Stopping container product-reviews
17m         Normal    Evicted                pod/product-reviews-58686f5fd9-dqgt6             Evicted pod: Underutilized
17m         Normal    Evicted                pod/frontend-75c8585d46-7kfzl                    Evicted pod: Underutilized
17m         Normal    Evicted                pod/checkout-5f59884d8-9nlwh                     Evicted pod: Underutilized
17m         Normal    Killing                pod/checkout-5f59884d8-9nlwh                     Stopping container checkout
17m         Normal    SuccessfulCreate       replicaset/checkout-5f59884d8                    Created pod: checkout-5f59884d8-ltz7v
17m         Normal    SuccessfulCreate       replicaset/email-746cdfc565                      Created pod: email-746cdfc565-59xwn
17m         Normal    Scheduled              pod/email-746cdfc565-59xwn                       Successfully assigned techx-corp-prod/email-746cdfc565-59xwn to ip-10-0-40-214.ec2.internal
17m         Normal    Nominated              pod/checkout-5f59884d8-9nlwh                     Pod should schedule on: nodeclaim/stateless-spot-8nqqg, node/ip-10-0-40-214.ec2.internal
17m         Normal    Evicted                pod/shipping-567ccf6f47-lxbdp                    Evicted pod: Underutilized
17m         Normal    Killing                pod/cart-6cbfb749cf-ft5cb                        Stopping container cart
17m         Normal    SuccessfulCreate       replicaset/shipping-567ccf6f47                   Created pod: shipping-567ccf6f47-jpz6z
17m         Normal    SuccessfulCreate       replicaset/ad-7998665c4b                         Created pod: ad-7998665c4b-g5hc8
17m         Normal    SuccessfulCreate       replicaset/currency-54d784bd7b                   Created pod: currency-54d784bd7b-mjrtn
17m         Normal    Pulling                pod/ad-7998665c4b-g5hc8                          Pulling image "493499579600.dkr.ecr.us-east-1.amazonaws.com/techx-prod-corp/ad:sha-fa6cb8f"
17m         Normal    Pulling                pod/accounting-69d676466f-6jtpf                  Pulling image "493499579600.dkr.ecr.us-east-1.amazonaws.com/techx-prod-corp/accounting:sha-fa6cb8f"
17m         Normal    Pulling                pod/cart-6cbfb749cf-zghqz                        Pulling image "busybox:1.37.0"
17m         Normal    Pulling                pod/product-reviews-58686f5fd9-qs6jg             Pulling image "public.ecr.aws/aws-cli/aws-cli:2.27.49"
17m         Normal    Pulled                 pod/cart-6cbfb749cf-zghqz                        Successfully pulled image "busybox:1.37.0" in 149ms (149ms including waiting). Image size: 1911349 bytes.
17m         Normal    Pulling                pod/email-746cdfc565-59xwn                       Pulling image "493499579600.dkr.ecr.us-east-1.amazonaws.com/techx-prod-corp/email:sha-fa6cb8f"
17m         Normal    Pulling                pod/shipping-567ccf6f47-jpz6z                    Pulling image "493499579600.dkr.ecr.us-east-1.amazonaws.com/techx-prod-corp/shipping:sha-fa6cb8f"
17m         Normal    Created                pod/cart-6cbfb749cf-zghqz                        Container created
17m         Normal    Pulling                pod/currency-54d784bd7b-mjrtn                    Pulling image "493499579600.dkr.ecr.us-east-1.amazonaws.com/techx-prod-corp/currency:sha-fa6cb8f"
17m         Normal    Pulling                pod/checkout-5f59884d8-ltz7v                     Pulling image "493499579600.dkr.ecr.us-east-1.amazonaws.com/techx-prod-corp/checkout:sha-fa6cb8f"
17m         Normal    Pulling                pod/frontend-75c8585d46-k6927                    Pulling image "493499579600.dkr.ecr.us-east-1.amazonaws.com/techx-prod-corp/frontend:sha-fa6cb8f"
17m         Normal    Started                pod/cart-6cbfb749cf-zghqz                        Container started
17m         Normal    Pulled                 pod/cart-6cbfb749cf-zghqz                        Container image "493499579600.dkr.ecr.us-east-1.amazonaws.com/techx-prod-corp/cart:sha-fa6cb8f" already present on machine and can be accessed by the pod
17m         Normal    Created                pod/cart-6cbfb749cf-zghqz                        Container created
17m         Normal    Started                pod/checkout-5f59884d8-ltz7v                     Container started
17m         Normal    Created                pod/checkout-5f59884d8-ltz7v                     Container created
17m         Normal    Pulled                 pod/checkout-5f59884d8-ltz7v                     Successfully pulled image "493499579600.dkr.ecr.us-east-1.amazonaws.com/techx-prod-corp/checkout:sha-fa6cb8f" in 1.717s (1.717s including waiting). Image size: 9514321 bytes.
17m         Normal    Started                pod/cart-6cbfb749cf-zghqz                        Container started
17m         Normal    Created                pod/accounting-69d676466f-6jtpf                  Container created
17m         Normal    Pulled                 pod/accounting-69d676466f-6jtpf                  Successfully pulled image "493499579600.dkr.ecr.us-east-1.amazonaws.com/techx-prod-corp/accounting:sha-fa6cb8f" in 3.386s (3.386s including waiting). Image size: 101851664 bytes.
17m         Normal    Started                pod/accounting-69d676466f-6jtpf                  Container started
17m         Warning   Unhealthy              pod/cart-6cbfb749cf-zghqz                        Readiness probe failed: timeout: failed to connect service "10.0.35.84:8080" within 3s: context deadline exceeded
17m         Normal    Started                pod/product-reviews-58686f5fd9-qs6jg             Container started
17m         Normal    Pulled                 pod/product-reviews-58686f5fd9-qs6jg             Successfully pulled image "public.ecr.aws/aws-cli/aws-cli:2.27.49" in 5.339s (5.339s including waiting). Image size: 130951142 bytes.
17m         Normal    Created                pod/product-reviews-58686f5fd9-qs6jg             Container created
17m         Normal    Pulled                 pod/shipping-567ccf6f47-jpz6z                    Successfully pulled image "493499579600.dkr.ecr.us-east-1.amazonaws.com/techx-prod-corp/shipping:sha-fa6cb8f" in 7.28s (7.28s including waiting). Image size: 15385507 bytes.
17m         Warning   Unhealthy              pod/shipping-567ccf6f47-jpz6z                    Readiness probe failed: dial tcp 10.0.37.240:8080: connect: connection refused
17m         Normal    Started                pod/shipping-567ccf6f47-jpz6z                    Container started
17m         Normal    Created                pod/shipping-567ccf6f47-jpz6z                    Container created
17m         Warning   Unhealthy              pod/cart-6cbfb749cf-zghqz                        Readiness probe failed: timeout: health rpc did not complete within 3s
17m         Normal    Pulled                 pod/currency-54d784bd7b-mjrtn                    Successfully pulled image "493499579600.dkr.ecr.us-east-1.amazonaws.com/techx-prod-corp/currency:sha-fa6cb8f" in 9.871s (9.871s including waiting). Image size: 30389101 bytes.
17m         Normal    Created                pod/currency-54d784bd7b-mjrtn                    Container created
17m         Normal    Created                pod/email-746cdfc565-59xwn                       Container created
17m         Normal    Started                pod/currency-54d784bd7b-mjrtn                    Container started
17m         Normal    Pulled                 pod/email-746cdfc565-59xwn                       Successfully pulled image "493499579600.dkr.ecr.us-east-1.amazonaws.com/techx-prod-corp/email:sha-fa6cb8f" in 11.025s (11.025s including waiting). Image size: 92375734 bytes.
17m         Normal    Started                pod/ad-7998665c4b-g5hc8                          Container started
17m         Normal    Pulled                 pod/ad-7998665c4b-g5hc8                          Successfully pulled image "493499579600.dkr.ecr.us-east-1.amazonaws.com/techx-prod-corp/ad:sha-fa6cb8f" in 11.621s (11.621s including waiting). Image size: 180887788 bytes.
17m         Normal    Created                pod/ad-7998665c4b-g5hc8                          Container created
17m         Warning   Unhealthy              pod/currency-54d784bd7b-s94g8                    Readiness probe failed: timeout: failed to connect service "10.0.45.6:8080" within 2s: context deadline exceeded
17m         Warning   Unhealthy              pod/cart-6cbfb749cf-ft5cb                        Readiness probe failed: timeout: failed to connect service "10.0.45.13:8080" within 3s: context deadline exceeded
17m         Normal    Started                pod/email-746cdfc565-59xwn                       Container started
17m         Warning   Unhealthy              pod/email-746cdfc565-59xwn                       Readiness probe failed: dial tcp 10.0.37.64:8080: connect: connection refused
17m         Warning   Unhealthy              pod/email-746cdfc565-59xwn                       Liveness probe failed: dial tcp 10.0.37.64:8080: connect: connection refused
17m         Normal    Pulled                 pod/frontend-75c8585d46-k6927                    Successfully pulled image "493499579600.dkr.ecr.us-east-1.amazonaws.com/techx-prod-corp/frontend:sha-fa6cb8f" in 14.69s (14.69s including waiting). Image size: 213499853 bytes.
17m         Normal    Created                pod/frontend-75c8585d46-k6927                    Container created
17m         Normal    Started                pod/frontend-75c8585d46-k6927                    Container started
17m         Warning   Unhealthy              pod/frontend-75c8585d46-k6927                    Readiness probe failed: Get "http://10.0.37.246:8080/": dial tcp 10.0.37.246:8080: connect: connection refused
16m         Normal    Killing                pod/otel-collector-agent-246dl                   Stopping container opentelemetry-collector
16m         Normal    Evicted                pod/otel-collector-agent-246dl                   Evicted pod: Underutilized
16m         Normal    Created                pod/product-reviews-58686f5fd9-qs6jg             Container created
16m         Normal    Pulled                 pod/product-reviews-58686f5fd9-qs6jg             Container image "busybox:1.37.0" already present on machine and can be accessed by the pod
16m         Normal    Started                pod/product-reviews-58686f5fd9-qs6jg             Container started
16m         Warning   Unhealthy              pod/ad-7998665c4b-g5hc8                          Liveness probe failed: timeout: failed to connect service "10.0.37.244:8080" within 5s: context deadline exceeded
16m         Warning   Unhealthy              pod/ad-7998665c4b-g5hc8                          Readiness probe failed: timeout: failed to connect service "10.0.37.244:8080" within 5s: context deadline exceeded
16m         Warning   FailedScheduling       pod/cart-6cbfb749cf-lprsl                        0/10 nodes are available: 1 node(s) didn't satisfy existing pods anti-affinity rules, 1 node(s) had untolerated taint(s), 2 node(s) didn't match Pod's node affinity/selector, 6 node(s) didn't match pod topology spread constraints. no new claims to deallocate, preemption: 0/10 nodes are available: 3 Preemption is not helpful for scheduling, 7 No preemption victims found for incoming pod.
16m         Warning   FailedScheduling       pod/cart-6cbfb749cf-6pg6k                        0/10 nodes are available: 1 node(s) didn't satisfy existing pods anti-affinity rules, 1 node(s) had untolerated taint(s), 2 node(s) didn't match Pod's node affinity/selector, 6 node(s) didn't match pod topology spread constraints. no new claims to deallocate, preemption: 0/10 nodes are available: 3 Preemption is not helpful for scheduling, 7 No preemption victims found for incoming pod.
16m         Warning   FailedScheduling       pod/cart-6cbfb749cf-7xl4m                        0/10 nodes are available: 1 node(s) didn't satisfy existing pods anti-affinity rules, 1 node(s) had untolerated taint(s), 2 node(s) didn't match Pod's node affinity/selector, 6 node(s) didn't match pod topology spread constraints. no new claims to deallocate, preemption: 0/10 nodes are available: 3 Preemption is not helpful for scheduling, 7 No preemption victims found for incoming pod.
16m         Normal    SuccessfulRescale      horizontalpodautoscaler/cart                     New size: 9; reason: cpu resource utilization (percentage of request) above target
16m         Normal    Nominated              pod/cart-6cbfb749cf-lprsl                        Pod should schedule on: nodeclaim/stateless-on-demand-kxxrf
16m         Normal    Nominated              pod/cart-6cbfb749cf-7xl4m                        Pod should schedule on: nodeclaim/stateless-spot-zrfm5
16m         Warning   FailedScheduling       pod/cart-6cbfb749cf-6pg6k                        Failed to schedule pod, all available instance types exceed limits for nodepool (NodePool=stateless-spot); all available instance types exceed limits for nodepool (NodePool=stateless-on-demand)
16m         Normal    NotTriggerScaleUp      pod/cart-6cbfb749cf-6pg6k                        pod didn't trigger scale-up: 2 node(s) didn't match Pod's node affinity/selector
16m         Normal    NotTriggerScaleUp      pod/cart-6cbfb749cf-7xl4m                        pod didn't trigger scale-up: 2 node(s) didn't match Pod's node affinity/selector
16m         Normal    NotTriggerScaleUp      pod/cart-6cbfb749cf-lprsl                        pod didn't trigger scale-up: 2 node(s) didn't match Pod's node affinity/selector
16m         Normal    Nominated              pod/cart-6cbfb749cf-6pg6k                        Pod should schedule on: nodeclaim/stateless-spot-tj66x
16m         Warning   FailedScheduling       pod/cart-6cbfb749cf-lprsl                        0/11 nodes are available: 1 node(s) didn't satisfy existing pods anti-affinity rules, 2 node(s) didn't match Pod's node affinity/selector, 2 node(s) had untolerated taint(s), 6 node(s) didn't match pod topology spread constraints. no new claims to deallocate, preemption: 0/11 nodes are available: 4 Preemption is not helpful for scheduling, 7 No preemption victims found for incoming pod.
16m         Warning   FailedScheduling       pod/cart-6cbfb749cf-7xl4m                        0/11 nodes are available: 1 node(s) didn't satisfy existing pods anti-affinity rules, 2 node(s) didn't match Pod's node affinity/selector, 2 node(s) had untolerated taint(s), 6 node(s) didn't match pod topology spread constraints. no new claims to deallocate, preemption: 0/11 nodes are available: 4 Preemption is not helpful for scheduling, 7 No preemption victims found for incoming pod.
16m         Warning   FailedScheduling       pod/cart-6cbfb749cf-6pg6k                        0/11 nodes are available: 1 node(s) didn't satisfy existing pods anti-affinity rules, 2 node(s) didn't match Pod's node affinity/selector, 2 node(s) had untolerated taint(s), 6 node(s) didn't match pod topology spread constraints. no new claims to deallocate, preemption: 0/11 nodes are available: 4 Preemption is not helpful for scheduling, 7 No preemption victims found for incoming pod.
15m         Warning   FailedScheduling       pod/cart-6cbfb749cf-6pg6k                        0/12 nodes are available: 1 node(s) didn't satisfy existing pods anti-affinity rules, 2 node(s) didn't match Pod's node affinity/selector, 3 node(s) had untolerated taint(s), 6 node(s) didn't match pod topology spread constraints. no new claims to deallocate, preemption: 0/12 nodes are available: 5 Preemption is not helpful for scheduling, 7 No preemption victims found for incoming pod.
15m         Warning   FailedScheduling       pod/cart-6cbfb749cf-7xl4m                        0/12 nodes are available: 1 node(s) didn't satisfy existing pods anti-affinity rules, 2 node(s) didn't match Pod's node affinity/selector, 3 node(s) had untolerated taint(s), 6 node(s) didn't match pod topology spread constraints. no new claims to deallocate, preemption: 0/12 nodes are available: 5 Preemption is not helpful for scheduling, 7 No preemption victims found for incoming pod.
15m         Warning   FailedScheduling       pod/cart-6cbfb749cf-lprsl                        0/12 nodes are available: 1 node(s) didn't satisfy existing pods anti-affinity rules, 2 node(s) didn't match Pod's node affinity/selector, 3 node(s) had untolerated taint(s), 6 node(s) didn't match pod topology spread constraints. no new claims to deallocate, preemption: 0/12 nodes are available: 5 Preemption is not helpful for scheduling, 7 No preemption victims found for incoming pod.
15m         Normal    NotTriggerScaleUp      pod/cart-6cbfb749cf-dwcvr                        pod didn't trigger scale-up: 2 node(s) didn't match Pod's node affinity/selector
15m         Normal    Nominated              pod/cart-6cbfb749cf-npfkp                        Pod should schedule on: nodeclaim/stateless-on-demand-kxxrf, node/ip-10-0-34-8.ec2.internal
15m         Warning   FailedScheduling       pod/cart-6cbfb749cf-mfk44                        0/13 nodes are available: 1 node(s) didn't satisfy existing pods anti-affinity rules, 2 node(s) didn't match Pod's node affinity/selector, 4 node(s) had untolerated taint(s), 6 node(s) didn't match pod topology spread constraints. no new claims to deallocate, preemption: 0/13 nodes are available: 6 Preemption is not helpful for scheduling, 7 No preemption victims found for incoming pod.
15m         Normal    NotTriggerScaleUp      pod/cart-6cbfb749cf-mfk44                        pod didn't trigger scale-up: 2 node(s) didn't match Pod's node affinity/selector
15m         Normal    NotTriggerScaleUp      pod/cart-6cbfb749cf-npfkp                        pod didn't trigger scale-up: 2 node(s) didn't match Pod's node affinity/selector
15m         Normal    Nominated              pod/cart-6cbfb749cf-mfk44                        Pod should schedule on: nodeclaim/stateless-spot-rgggn
15m         Warning   FailedScheduling       pod/cart-6cbfb749cf-dwcvr                        0/13 nodes are available: 1 node(s) didn't satisfy existing pods anti-affinity rules, 2 node(s) didn't match Pod's node affinity/selector, 4 node(s) had untolerated taint(s), 6 node(s) didn't match pod topology spread constraints. no new claims to deallocate, preemption: 0/13 nodes are available: 6 Preemption is not helpful for scheduling, 7 No preemption victims found for incoming pod.
15m         Warning   FailedScheduling       pod/cart-6cbfb749cf-6pg6k                        0/13 nodes are available: 1 node(s) didn't satisfy existing pods anti-affinity rules, 2 node(s) didn't match Pod's node affinity/selector, 4 node(s) had untolerated taint(s), 6 node(s) didn't match pod topology spread constraints. no new claims to deallocate, preemption: 0/13 nodes are available: 6 Preemption is not helpful for scheduling, 7 No preemption victims found for incoming pod.
15m         Normal    Nominated              pod/cart-6cbfb749cf-dwcvr                        Pod should schedule on: nodeclaim/stateless-on-demand-sxbhq
15m         Warning   FailedScheduling       pod/cart-6cbfb749cf-7xl4m                        0/13 nodes are available: 1 node(s) didn't satisfy existing pods anti-affinity rules, 2 node(s) didn't match Pod's node affinity/selector, 4 node(s) had untolerated taint(s), 6 node(s) didn't match pod topology spread constraints. no new claims to deallocate, preemption: 0/13 nodes are available: 6 Preemption is not helpful for scheduling, 7 No preemption victims found for incoming pod.
15m         Warning   FailedScheduling       pod/cart-6cbfb749cf-lprsl                        0/13 nodes are available: 1 node(s) didn't satisfy existing pods anti-affinity rules, 2 node(s) didn't match Pod's node affinity/selector, 4 node(s) had untolerated taint(s), 6 node(s) didn't match pod topology spread constraints. no new claims to deallocate, preemption: 0/13 nodes are available: 6 Preemption is not helpful for scheduling, 7 No preemption victims found for incoming pod.
15m         Warning   FailedScheduling       pod/cart-6cbfb749cf-npfkp                        0/13 nodes are available: 1 node(s) didn't satisfy existing pods anti-affinity rules, 2 node(s) didn't match Pod's node affinity/selector, 4 node(s) had untolerated taint(s), 6 node(s) didn't match pod topology spread constraints. no new claims to deallocate, preemption: 0/13 nodes are available: 6 Preemption is not helpful for scheduling, 7 No preemption victims found for incoming pod.
15m         Normal    Pulling                pod/product-reviews-58686f5fd9-qs6jg             Pulling image "493499579600.dkr.ecr.us-east-1.amazonaws.com/techx-prod-corp/product-reviews:sha-fa6cb8f"
15m         Warning   FailedScheduling       pod/cart-6cbfb749cf-lprsl                        0/14 nodes are available: 1 node(s) didn't satisfy existing pods anti-affinity rules, 2 node(s) didn't match Pod's node affinity/selector, 5 node(s) had untolerated taint(s), 6 node(s) didn't match pod topology spread constraints. no new claims to deallocate, preemption: 0/14 nodes are available: 7 No preemption victims found for incoming pod, 7 Preemption is not helpful for scheduling.
15m         Warning   FailedScheduling       pod/cart-6cbfb749cf-7xl4m                        0/14 nodes are available: 1 node(s) didn't satisfy existing pods anti-affinity rules, 2 node(s) didn't match Pod's node affinity/selector, 5 node(s) had untolerated taint(s), 6 node(s) didn't match pod topology spread constraints. no new claims to deallocate, preemption: 0/14 nodes are available: 7 No preemption victims found for incoming pod, 7 Preemption is not helpful for scheduling.
15m         Warning   FailedScheduling       pod/cart-6cbfb749cf-6pg6k                        0/14 nodes are available: 1 node(s) didn't satisfy existing pods anti-affinity rules, 2 node(s) didn't match Pod's node affinity/selector, 5 node(s) had untolerated taint(s), 6 node(s) didn't match pod topology spread constraints. no new claims to deallocate, preemption: 0/14 nodes are available: 7 No preemption victims found for incoming pod, 7 Preemption is not helpful for scheduling.
15m         Normal    SuccessfulCreate       daemonset/otel-collector-agent                   Created pod: otel-collector-agent-2qtfd
15m         Normal    Scheduled              pod/cart-6cbfb749cf-lprsl                        Successfully assigned techx-corp-prod/cart-6cbfb749cf-lprsl to ip-10-0-24-165.ec2.internal
15m         Warning   FailedScheduling       pod/cart-6cbfb749cf-npfkp                        0/14 nodes are available: 1 node(s) didn't satisfy existing pods anti-affinity rules, 2 node(s) didn't match Pod's node affinity/selector, 5 node(s) had untolerated taint(s), 6 node(s) didn't match pod topology spread constraints. no new claims to deallocate, preemption: 0/14 nodes are available: 7 No preemption victims found for incoming pod, 7 Preemption is not helpful for scheduling.
15m         Warning   FailedScheduling       pod/cart-6cbfb749cf-mfk44                        0/14 nodes are available: 1 node(s) didn't satisfy existing pods anti-affinity rules, 2 node(s) didn't match Pod's node affinity/selector, 5 node(s) had untolerated taint(s), 6 node(s) didn't match pod topology spread constraints. no new claims to deallocate, preemption: 0/14 nodes are available: 7 No preemption victims found for incoming pod, 7 Preemption is not helpful for scheduling.
15m         Warning   FailedScheduling       pod/cart-6cbfb749cf-npfkp                        0/14 nodes are available: 2 node(s) didn't match Pod's node affinity/selector, 4 node(s) had untolerated taint(s), 8 node(s) didn't match pod topology spread constraints. no new claims to deallocate, preemption: 0/14 nodes are available: 6 Preemption is not helpful for scheduling, 8 No preemption victims found for incoming pod.
15m         Warning   FailedScheduling       pod/cart-6cbfb749cf-dwcvr                        0/14 nodes are available: 2 node(s) didn't match Pod's node affinity/selector, 4 node(s) had untolerated taint(s), 8 node(s) didn't match pod topology spread constraints. no new claims to deallocate, preemption: 0/14 nodes are available: 6 Preemption is not helpful for scheduling, 8 No preemption victims found for incoming pod.
15m         Warning   FailedScheduling       pod/cart-6cbfb749cf-dwcvr                        0/14 nodes are available: 1 node(s) didn't satisfy existing pods anti-affinity rules, 2 node(s) didn't match Pod's node affinity/selector, 5 node(s) had untolerated taint(s), 6 node(s) didn't match pod topology spread constraints. no new claims to deallocate, preemption: 0/14 nodes are available: 7 No preemption victims found for incoming pod, 7 Preemption is not helpful for scheduling.
15m         Normal    Scheduled              pod/otel-collector-agent-2qtfd                   Successfully assigned techx-corp-prod/otel-collector-agent-2qtfd to ip-10-0-24-165.ec2.internal
15m         Warning   FailedScheduling       pod/cart-6cbfb749cf-mfk44                        0/14 nodes are available: 2 node(s) didn't match Pod's node affinity/selector, 4 node(s) had untolerated taint(s), 8 node(s) didn't match pod topology spread constraints. no new claims to deallocate, preemption: 0/14 nodes are available: 6 Preemption is not helpful for scheduling, 8 No preemption victims found for incoming pod.
15m         Normal    Pulling                pod/cart-6cbfb749cf-lprsl                        Pulling image "busybox:1.37.0"
15m         Warning   FailedScheduling       pod/cart-6cbfb749cf-6pg6k                        0/14 nodes are available: 2 node(s) didn't match Pod's node affinity/selector, 4 node(s) had untolerated taint(s), 8 node(s) didn't match pod topology spread constraints. no new claims to deallocate, preemption: 0/14 nodes are available: 6 Preemption is not helpful for scheduling, 8 No preemption victims found for incoming pod.
15m         Normal    SuccessfulRescale      horizontalpodautoscaler/load-generator-worker    New size: 3; reason: All metrics below target
15m         Normal    Pulling                pod/otel-collector-agent-2qtfd                   Pulling image "otel/opentelemetry-collector-contrib:0.151.0"
15m         Normal    Scheduled              pod/cart-6cbfb749cf-npfkp                        Successfully assigned techx-corp-prod/cart-6cbfb749cf-npfkp to ip-10-0-34-8.ec2.internal
15m         Normal    Killing                pod/load-generator-worker-cdc7df7c5-78d9m        Stopping container load-generator-worker
15m         Normal    SuccessfulDelete       replicaset/load-generator-worker-cdc7df7c5       Deleted pod: load-generator-worker-cdc7df7c5-78d9m
15m         Warning   FailedScheduling       pod/cart-6cbfb749cf-7xl4m                        0/14 nodes are available: 2 node(s) didn't match Pod's node affinity/selector, 4 node(s) had untolerated taint(s), 8 node(s) didn't match pod topology spread constraints. no new claims to deallocate, preemption: 0/14 nodes are available: 6 Preemption is not helpful for scheduling, 8 No preemption victims found for incoming pod.
15m         Normal    ScalingReplicaSet      deployment/load-generator-worker                 Scaled down replica set load-generator-worker-cdc7df7c5 from 4 to 3
15m         Normal    Scheduled              pod/otel-collector-agent-vpwm5                   Successfully assigned techx-corp-prod/otel-collector-agent-vpwm5 to ip-10-0-34-8.ec2.internal
15m         Normal    Pulled                 pod/cart-6cbfb749cf-lprsl                        Successfully pulled image "busybox:1.37.0" in 555ms (555ms including waiting). Image size: 1911349 bytes.
15m         Normal    TaintManagerEviction   pod/cart-6cbfb749cf-lprsl                        Cancelling deletion of Pod techx-corp-prod/cart-6cbfb749cf-lprsl
15m         Normal    Started                pod/cart-6cbfb749cf-lprsl                        Container started
15m         Warning   FailedScheduling       pod/cart-6cbfb749cf-7xl4m                        0/14 nodes are available: 1 node(s) didn't satisfy existing pods anti-affinity rules, 2 node(s) didn't match Pod's node affinity/selector, 3 node(s) had untolerated taint(s), 8 node(s) didn't match pod topology spread constraints. no new claims to deallocate, preemption: 0/14 nodes are available: 5 Preemption is not helpful for scheduling, 9 No preemption victims found for incoming pod.
15m         Normal    Pulling                pod/otel-collector-agent-vpwm5                   Pulling image "otel/opentelemetry-collector-contrib:0.151.0"
15m         Normal    Created                pod/cart-6cbfb749cf-lprsl                        Container created
15m         Warning   FailedScheduling       pod/cart-6cbfb749cf-mfk44                        0/14 nodes are available: 1 node(s) didn't satisfy existing pods anti-affinity rules, 2 node(s) didn't match Pod's node affinity/selector, 3 node(s) had untolerated taint(s), 8 node(s) didn't match pod topology spread constraints. no new claims to deallocate, preemption: 0/14 nodes are available: 5 Preemption is not helpful for scheduling, 9 No preemption victims found for incoming pod.
15m         Normal    SuccessfulCreate       daemonset/otel-collector-agent                   Created pod: otel-collector-agent-vpwm5
15m         Normal    Pulling                pod/cart-6cbfb749cf-npfkp                        Pulling image "busybox:1.37.0"
15m         Warning   FailedScheduling       pod/cart-6cbfb749cf-6pg6k                        0/14 nodes are available: 1 node(s) didn't satisfy existing pods anti-affinity rules, 2 node(s) didn't match Pod's node affinity/selector, 3 node(s) had untolerated taint(s), 8 node(s) didn't match pod topology spread constraints. no new claims to deallocate, preemption: 0/14 nodes are available: 5 Preemption is not helpful for scheduling, 9 No preemption victims found for incoming pod.
15m         Warning   FailedScheduling       pod/cart-6cbfb749cf-dwcvr                        0/14 nodes are available: 1 node(s) didn't satisfy existing pods anti-affinity rules, 2 node(s) didn't match Pod's node affinity/selector, 3 node(s) had untolerated taint(s), 8 node(s) didn't match pod topology spread constraints. no new claims to deallocate, preemption: 0/14 nodes are available: 5 Preemption is not helpful for scheduling, 9 No preemption victims found for incoming pod.
15m         Normal    TaintManagerEviction   pod/cart-6cbfb749cf-npfkp                        Cancelling deletion of Pod techx-corp-prod/cart-6cbfb749cf-npfkp
15m         Normal    Created                pod/cart-6cbfb749cf-npfkp                        Container created
15m         Warning   FailedScheduling       pod/cart-6cbfb749cf-mfk44                        0/13 nodes are available: 1 node(s) didn't satisfy existing pods anti-affinity rules, 2 node(s) didn't match Pod's node affinity/selector, 2 node(s) had untolerated taint(s), 8 node(s) didn't match pod topology spread constraints. no new claims to deallocate, preemption: 0/13 nodes are available: 4 Preemption is not helpful for scheduling, 9 No preemption victims found for incoming pod.
15m         Normal    Pulled                 pod/cart-6cbfb749cf-npfkp                        Successfully pulled image "busybox:1.37.0" in 583ms (583ms including waiting). Image size: 1911349 bytes.
15m         Warning   FailedScheduling       pod/cart-6cbfb749cf-dwcvr                        0/13 nodes are available: 1 node(s) didn't satisfy existing pods anti-affinity rules, 2 node(s) didn't match Pod's node affinity/selector, 2 node(s) had untolerated taint(s), 8 node(s) didn't match pod topology spread constraints. no new claims to deallocate, preemption: 0/13 nodes are available: 4 Preemption is not helpful for scheduling, 9 No preemption victims found for incoming pod.
15m         Normal    Started                pod/cart-6cbfb749cf-npfkp                        Container started
15m         Warning   FailedScheduling       pod/cart-6cbfb749cf-6pg6k                        0/13 nodes are available: 1 node(s) didn't satisfy existing pods anti-affinity rules, 2 node(s) didn't match Pod's node affinity/selector, 2 node(s) had untolerated taint(s), 8 node(s) didn't match pod topology spread constraints. no new claims to deallocate, preemption: 0/13 nodes are available: 4 Preemption is not helpful for scheduling, 9 No preemption victims found for incoming pod.
15m         Warning   FailedScheduling       pod/cart-6cbfb749cf-7xl4m                        0/13 nodes are available: 1 node(s) didn't satisfy existing pods anti-affinity rules, 2 node(s) didn't match Pod's node affinity/selector, 2 node(s) had untolerated taint(s), 8 node(s) didn't match pod topology spread constraints. no new claims to deallocate, preemption: 0/13 nodes are available: 4 Preemption is not helpful for scheduling, 9 No preemption victims found for incoming pod.
15m         Normal    Scheduled              pod/otel-collector-agent-4slsx                   Successfully assigned techx-corp-prod/otel-collector-agent-4slsx to ip-10-0-45-80.ec2.internal
15m         Warning   FailedScheduling       pod/cart-6cbfb749cf-7xl4m                        0/13 nodes are available: 1 node(s) didn't satisfy existing pods anti-affinity rules, 1 node(s) had untolerated taint(s), 2 node(s) didn't match Pod's node affinity/selector, 9 node(s) didn't match pod topology spread constraints. no new claims to deallocate, preemption: 0/13 nodes are available: 10 No preemption victims found for incoming pod, 3 Preemption is not helpful for scheduling.
15m         Normal    Pulling                pod/cart-6cbfb749cf-mfk44                        Pulling image "busybox:1.37.0"
15m         Normal    Scheduled              pod/cart-6cbfb749cf-mfk44                        Successfully assigned techx-corp-prod/cart-6cbfb749cf-mfk44 to ip-10-0-45-80.ec2.internal
15m         Warning   FailedScheduling       pod/cart-6cbfb749cf-6pg6k                        0/13 nodes are available: 1 node(s) didn't satisfy existing pods anti-affinity rules, 1 node(s) had untolerated taint(s), 2 node(s) didn't match Pod's node affinity/selector, 9 node(s) didn't match pod topology spread constraints. no new claims to deallocate, preemption: 0/13 nodes are available: 10 No preemption victims found for incoming pod, 3 Preemption is not helpful for scheduling.
15m         Normal    SuccessfulCreate       daemonset/otel-collector-agent                   Created pod: otel-collector-agent-4slsx
15m         Normal    Pulling                pod/otel-collector-agent-4slsx                   Pulling image "otel/opentelemetry-collector-contrib:0.151.0"
15m         Normal    Pulling                pod/cart-6cbfb749cf-lprsl                        Pulling image "493499579600.dkr.ecr.us-east-1.amazonaws.com/techx-prod-corp/cart:sha-fa6cb8f"
15m         Normal    Started                pod/cart-6cbfb749cf-mfk44                        Container started
15m         Normal    Created                pod/cart-6cbfb749cf-mfk44                        Container created
15m         Normal    Pulled                 pod/cart-6cbfb749cf-mfk44                        Successfully pulled image "busybox:1.37.0" in 543ms (543ms including waiting). Image size: 1911349 bytes.
15m         Normal    Pulling                pod/cart-6cbfb749cf-npfkp                        Pulling image "493499579600.dkr.ecr.us-east-1.amazonaws.com/techx-prod-corp/cart:sha-fa6cb8f"
15m         Warning   FailedScheduling       pod/cart-6cbfb749cf-dwcvr                        0/13 nodes are available: 1 node(s) didn't satisfy existing pods anti-affinity rules, 1 node(s) had untolerated taint(s), 2 node(s) didn't match Pod's node affinity/selector, 9 node(s) didn't match pod topology spread constraints. no new claims to deallocate, preemption: 0/13 nodes are available: 10 No preemption victims found for incoming pod, 3 Preemption is not helpful for scheduling.
15m         Normal    TaintManagerEviction   pod/cart-6cbfb749cf-mfk44                        Cancelling deletion of Pod techx-corp-prod/cart-6cbfb749cf-mfk44
15m         Normal    Created                pod/cart-6cbfb749cf-lprsl                        Container created
15m         Normal    Pulled                 pod/cart-6cbfb749cf-lprsl                        Successfully pulled image "493499579600.dkr.ecr.us-east-1.amazonaws.com/techx-prod-corp/cart:sha-fa6cb8f" in 2.727s (2.728s including waiting). Image size: 50820594 bytes.
15m         Normal    Started                pod/cart-6cbfb749cf-lprsl                        Container started
15m         Normal    Pulled                 pod/cart-6cbfb749cf-npfkp                        Successfully pulled image "493499579600.dkr.ecr.us-east-1.amazonaws.com/techx-prod-corp/cart:sha-fa6cb8f" in 2.917s (2.917s including waiting). Image size: 50820594 bytes.
15m         Normal    Pulling                pod/cart-6cbfb749cf-mfk44                        Pulling image "493499579600.dkr.ecr.us-east-1.amazonaws.com/techx-prod-corp/cart:sha-fa6cb8f"
15m         Normal    Started                pod/otel-collector-agent-2qtfd                   Container started
15m         Normal    Created                pod/otel-collector-agent-2qtfd                   Container created
15m         Normal    Pulled                 pod/otel-collector-agent-2qtfd                   Successfully pulled image "otel/opentelemetry-collector-contrib:0.151.0" in 6.606s (6.606s including waiting). Image size: 88803327 bytes.
15m         Normal    Created                pod/otel-collector-agent-4slsx                   Container created
15m         Normal    Pulled                 pod/otel-collector-agent-4slsx                   Successfully pulled image "otel/opentelemetry-collector-contrib:0.151.0" in 4.537s (4.537s including waiting). Image size: 88803327 bytes.
15m         Normal    Started                pod/cart-6cbfb749cf-npfkp                        Container started
15m         Normal    Pulled                 pod/otel-collector-agent-vpwm5                   Successfully pulled image "otel/opentelemetry-collector-contrib:0.151.0" in 6.645s (6.645s including waiting). Image size: 88803327 bytes.
15m         Normal    Created                pod/otel-collector-agent-vpwm5                   Container created
15m         Normal    Started                pod/otel-collector-agent-vpwm5                   Container started
15m         Normal    Created                pod/cart-6cbfb749cf-npfkp                        Container created
15m         Normal    Started                pod/otel-collector-agent-4slsx                   Container started
15m         Normal    Pulled                 pod/cart-6cbfb749cf-mfk44                        Successfully pulled image "493499579600.dkr.ecr.us-east-1.amazonaws.com/techx-prod-corp/cart:sha-fa6cb8f" in 2.416s (2.416s including waiting). Image size: 50820594 bytes.
15m         Normal    Created                pod/cart-6cbfb749cf-mfk44                        Container created
15m         Normal    Started                pod/cart-6cbfb749cf-mfk44                        Container started
15m         Normal    Scheduled              pod/otel-collector-agent-zccmp                   Successfully assigned techx-corp-prod/otel-collector-agent-zccmp to ip-10-0-17-84.ec2.internal
15m         Normal    Scheduled              pod/cart-6cbfb749cf-7xl4m                        Successfully assigned techx-corp-prod/cart-6cbfb749cf-7xl4m to ip-10-0-17-84.ec2.internal
15m         Normal    Pulling                pod/cart-6cbfb749cf-7xl4m                        Pulling image "busybox:1.37.0"
15m         Normal    Pulling                pod/otel-collector-agent-zccmp                   Pulling image "otel/opentelemetry-collector-contrib:0.151.0"
15m         Normal    Started                pod/cart-6cbfb749cf-7xl4m                        Container started
15m         Normal    Pulled                 pod/cart-6cbfb749cf-7xl4m                        Successfully pulled image "busybox:1.37.0" in 534ms (534ms including waiting). Image size: 1911349 bytes.
15m         Normal    TaintManagerEviction   pod/cart-6cbfb749cf-7xl4m                        Cancelling deletion of Pod techx-corp-prod/cart-6cbfb749cf-7xl4m
15m         Normal    Created                pod/cart-6cbfb749cf-7xl4m                        Container created
15m         Warning   Unhealthy              pod/cart-6cbfb749cf-npfkp                        Readiness probe failed: timeout: failed to connect service "10.0.40.128:8080" within 3s: context deadline exceeded
15m         Warning   Unhealthy              pod/cart-6cbfb749cf-mfk44                        Readiness probe failed: timeout: failed to connect service "10.0.34.128:8080" within 3s: context deadline exceeded
15m         Warning   Unhealthy              pod/cart-6cbfb749cf-npfkp                        Liveness probe failed: dial tcp 10.0.40.128:8080: connect: connection refused
15m         Warning   Unhealthy              pod/cart-6cbfb749cf-npfkp                        Readiness probe failed: timeout: health rpc did not complete within 3s
15m         Normal    Pulling                pod/cart-6cbfb749cf-7xl4m                        Pulling image "493499579600.dkr.ecr.us-east-1.amazonaws.com/techx-prod-corp/cart:sha-fa6cb8f"
15m         Warning   FailedScheduling       pod/cart-6cbfb749cf-dwcvr                        0/13 nodes are available: 1 node(s) didn't satisfy existing pods anti-affinity rules, 10 node(s) didn't match pod topology spread constraints, 2 node(s) didn't match Pod's node affinity/selector. no new claims to deallocate, preemption: 0/13 nodes are available: 11 No preemption victims found for incoming pod, 2 Preemption is not helpful for scheduling.
15m         Normal    Started                pod/otel-collector-agent-zccmp                   Container started
15m         Normal    Pulled                 pod/otel-collector-agent-zccmp                   Successfully pulled image "otel/opentelemetry-collector-contrib:0.151.0" in 6.451s (6.451s including waiting). Image size: 88803327 bytes.
15m         Normal    Pulled                 pod/cart-6cbfb749cf-7xl4m                        Successfully pulled image "493499579600.dkr.ecr.us-east-1.amazonaws.com/techx-prod-corp/cart:sha-fa6cb8f" in 2.741s (2.741s including waiting). Image size: 50820594 bytes.
15m         Normal    Created                pod/otel-collector-agent-zccmp                   Container created
15m         Normal    Created                pod/cart-6cbfb749cf-7xl4m                        Container created
15m         Normal    Started                pod/cart-6cbfb749cf-7xl4m                        Container started
15m         Warning   FailedScheduling       pod/cart-6cbfb749cf-dwcvr                        0/14 nodes are available: 1 node(s) didn't satisfy existing pods anti-affinity rules, 1 node(s) had untolerated taint(s), 10 node(s) didn't match pod topology spread constraints, 2 node(s) didn't match Pod's node affinity/selector. no new claims to deallocate, preemption: 0/14 nodes are available: 11 No preemption victims found for incoming pod, 3 Preemption is not helpful for scheduling.
15m         Warning   FailedScheduling       pod/cart-6cbfb749cf-dwcvr                        0/15 nodes are available: 1 node(s) didn't satisfy existing pods anti-affinity rules, 10 node(s) didn't match pod topology spread constraints, 2 node(s) didn't match Pod's node affinity/selector, 2 node(s) had untolerated taint(s). no new claims to deallocate, preemption: 0/15 nodes are available: 11 No preemption victims found for incoming pod, 4 Preemption is not helpful for scheduling.
15m         Warning   Unhealthy              pod/cart-6cbfb749cf-7xl4m                        Readiness probe failed: timeout: failed to connect service "10.0.19.176:8080" within 3s: context deadline exceeded
15m         Normal    Started                pod/product-reviews-58686f5fd9-qs6jg             Container started
15m         Normal    Created                pod/product-reviews-58686f5fd9-qs6jg             Container created
15m         Normal    Pulled                 pod/product-reviews-58686f5fd9-qs6jg             Successfully pulled image "493499579600.dkr.ecr.us-east-1.amazonaws.com/techx-prod-corp/product-reviews:sha-fa6cb8f" in 25.235s (25.235s including waiting). Image size: 732871123 bytes.
15m         Warning   Unhealthy              pod/cart-6cbfb749cf-7xl4m                        Readiness probe failed: timeout: health rpc did not complete within 3s
15m         Normal    Scheduled              pod/cart-6cbfb749cf-dwcvr                        Successfully assigned techx-corp-prod/cart-6cbfb749cf-dwcvr to ip-10-0-38-109.ec2.internal
15m         Normal    Scheduled              pod/otel-collector-agent-lsrlv                   Successfully assigned techx-corp-prod/otel-collector-agent-lsrlv to ip-10-0-38-109.ec2.internal
15m         Normal    Pulled                 pod/cart-6cbfb749cf-dwcvr                        Successfully pulled image "busybox:1.37.0" in 532ms (532ms including waiting). Image size: 1911349 bytes.
15m         Normal    Pulling                pod/otel-collector-agent-lsrlv                   Pulling image "otel/opentelemetry-collector-contrib:0.151.0"
15m         Normal    Pulling                pod/cart-6cbfb749cf-6pg6k                        Pulling image "busybox:1.37.0"
15m         Normal    Scheduled              pod/cart-6cbfb749cf-6pg6k                        Successfully assigned techx-corp-prod/cart-6cbfb749cf-6pg6k to ip-10-0-26-197.ec2.internal
15m         Normal    Scheduled              pod/otel-collector-agent-97kvz                   Successfully assigned techx-corp-prod/otel-collector-agent-97kvz to ip-10-0-26-197.ec2.internal
15m         Normal    Started                pod/cart-6cbfb749cf-dwcvr                        Container started
15m         Normal    Created                pod/cart-6cbfb749cf-dwcvr                        Container created
15m         Normal    Pulling                pod/cart-6cbfb749cf-dwcvr                        Pulling image "busybox:1.37.0"
15m         Normal    Created                pod/cart-6cbfb749cf-6pg6k                        Container created
15m         Normal    Started                pod/cart-6cbfb749cf-6pg6k                        Container started
15m         Normal    Pulled                 pod/cart-6cbfb749cf-6pg6k                        Successfully pulled image "busybox:1.37.0" in 606ms (606ms including waiting). Image size: 1911349 bytes.
15m         Normal    Pulling                pod/otel-collector-agent-97kvz                   Pulling image "otel/opentelemetry-collector-contrib:0.151.0"
15m         Normal    Pulling                pod/cart-6cbfb749cf-dwcvr                        Pulling image "493499579600.dkr.ecr.us-east-1.amazonaws.com/techx-prod-corp/cart:sha-fa6cb8f"
15m         Normal    Scheduled              pod/otel-collector-agent-4c4s8                   Successfully assigned techx-corp-prod/otel-collector-agent-4c4s8 to ip-10-0-17-52.ec2.internal
15m         Normal    TaintManagerEviction   pod/cart-6cbfb749cf-6pg6k                        Cancelling deletion of Pod techx-corp-prod/cart-6cbfb749cf-6pg6k
15m         Normal    TaintManagerEviction   pod/cart-6cbfb749cf-dwcvr                        Cancelling deletion of Pod techx-corp-prod/cart-6cbfb749cf-dwcvr
15m         Normal    Pulling                pod/otel-collector-agent-4c4s8                   Pulling image "otel/opentelemetry-collector-contrib:0.151.0"
15m         Normal    Pulling                pod/cart-6cbfb749cf-6pg6k                        Pulling image "493499579600.dkr.ecr.us-east-1.amazonaws.com/techx-prod-corp/cart:sha-fa6cb8f"
15m         Normal    Pulled                 pod/cart-6cbfb749cf-dwcvr                        Successfully pulled image "493499579600.dkr.ecr.us-east-1.amazonaws.com/techx-prod-corp/cart:sha-fa6cb8f" in 2.599s (2.599s including waiting). Image size: 50820594 bytes.
15m         Normal    Created                pod/cart-6cbfb749cf-dwcvr                        Container created
15m         Normal    Started                pod/cart-6cbfb749cf-dwcvr                        Container started
15m         Normal    Pulled                 pod/otel-collector-agent-lsrlv                   Successfully pulled image "otel/opentelemetry-collector-contrib:0.151.0" in 5.092s (5.092s including waiting). Image size: 88803327 bytes.
15m         Normal    Created                pod/otel-collector-agent-lsrlv                   Container created
15m         Normal    Started                pod/otel-collector-agent-lsrlv                   Container started
15m         Normal    Started                pod/otel-collector-agent-4c4s8                   Container started
15m         Normal    Created                pod/otel-collector-agent-4c4s8                   Container created
15m         Normal    Pulled                 pod/otel-collector-agent-4c4s8                   Successfully pulled image "otel/opentelemetry-collector-contrib:0.151.0" in 4.696s (4.696s including waiting). Image size: 88803327 bytes.
15m         Warning   Unhealthy              pod/cart-6cbfb749cf-dwcvr                        Readiness probe failed: timeout: failed to connect service "10.0.44.80:8080" within 3s: context deadline exceeded
15m         Normal    Started                pod/cart-6cbfb749cf-6pg6k                        Container started
15m         Normal    Created                pod/cart-6cbfb749cf-6pg6k                        Container created
15m         Normal    Pulled                 pod/cart-6cbfb749cf-6pg6k                        Successfully pulled image "493499579600.dkr.ecr.us-east-1.amazonaws.com/techx-prod-corp/cart:sha-fa6cb8f" in 2.791s (2.791s including waiting). Image size: 50820594 bytes.
15m         Normal    Started                pod/otel-collector-agent-97kvz                   Container started
15m         Normal    Created                pod/otel-collector-agent-97kvz                   Container created
15m         Normal    Pulled                 pod/otel-collector-agent-97kvz                   Successfully pulled image "otel/opentelemetry-collector-contrib:0.151.0" in 6.75s (6.75s including waiting). Image size: 88803327 bytes.
15m         Warning   Unhealthy              pod/cart-6cbfb749cf-6pg6k                        Readiness probe failed: timeout: failed to connect service "10.0.19.128:8080" within 3s: context deadline exceeded
15m         Warning   Unhealthy              pod/product-reviews-58686f5fd9-qs6jg             Startup probe failed: timeout: failed to connect service "10.0.35.81:3551" within 5s: context deadline exceeded
15m         Warning   Unhealthy              pod/cart-6cbfb749cf-6pg6k                        Readiness probe failed: timeout: health rpc did not complete within 3s
14m         Normal    Evicted                pod/checkout-5f59884d8-2wqb9                     Evicted pod: Underutilized
14m         Normal    Pulling                pod/checkout-5f59884d8-rnb5m                     Pulling image "493499579600.dkr.ecr.us-east-1.amazonaws.com/techx-prod-corp/checkout:sha-fa6cb8f"
14m         Normal    Pulling                pod/cart-6cbfb749cf-zw6b8                        Pulling image "busybox:1.37.0"
14m         Normal    Scheduled              pod/cart-6cbfb749cf-zw6b8                        Successfully assigned techx-corp-prod/cart-6cbfb749cf-zw6b8 to ip-10-0-17-52.ec2.internal
14m         Normal    Evicted                pod/cart-6cbfb749cf-ncznm                        Evicted pod: Underutilized
14m         Normal    Killing                pod/cart-6cbfb749cf-ncznm                        Stopping container cart
14m         Normal    Nominated              pod/checkout-5f59884d8-2wqb9                     Pod should schedule on: nodeclaim/stateless-spot-5lbqh, node/ip-10-0-17-52.ec2.internal
14m         Normal    Killing                pod/checkout-5f59884d8-2wqb9                     Stopping container checkout
14m         Normal    Scheduled              pod/frontend-75c8585d46-czn5b                    Successfully assigned techx-corp-prod/frontend-75c8585d46-czn5b to ip-10-0-24-165.ec2.internal
14m         Normal    Nominated              pod/cart-6cbfb749cf-ncznm                        Pod should schedule on: nodeclaim/stateless-spot-5lbqh, node/ip-10-0-17-52.ec2.internal
14m         Normal    Scheduled              pod/checkout-5f59884d8-rnb5m                     Successfully assigned techx-corp-prod/checkout-5f59884d8-rnb5m to ip-10-0-17-84.ec2.internal
14m         Normal    SuccessfulCreate       replicaset/frontend-75c8585d46                   Created pod: frontend-75c8585d46-czn5b
14m         Normal    SuccessfulCreate       replicaset/checkout-5f59884d8                    Created pod: checkout-5f59884d8-rnb5m
14m         Normal    Nominated              pod/frontend-75c8585d46-f4jh8                    Pod should schedule on: nodeclaim/stateless-spot-5lbqh, node/ip-10-0-17-52.ec2.internal
14m         Normal    Killing                pod/frontend-75c8585d46-f4jh8                    Stopping container frontend
14m         Normal    Evicted                pod/frontend-75c8585d46-f4jh8                    Evicted pod: Underutilized
14m         Normal    Pulling                pod/frontend-75c8585d46-czn5b                    Pulling image "493499579600.dkr.ecr.us-east-1.amazonaws.com/techx-prod-corp/frontend:sha-fa6cb8f"
14m         Normal    Started                pod/cart-6cbfb749cf-zw6b8                        Container started
14m         Normal    Created                pod/cart-6cbfb749cf-zw6b8                        Container created
14m         Normal    Pulled                 pod/cart-6cbfb749cf-zw6b8                        Successfully pulled image "busybox:1.37.0" in 691ms (691ms including waiting). Image size: 1911349 bytes.
14m         Normal    Started                pod/checkout-5f59884d8-rnb5m                     Container started
14m         Normal    Created                pod/checkout-5f59884d8-rnb5m                     Container created
14m         Normal    Pulled                 pod/checkout-5f59884d8-rnb5m                     Successfully pulled image "493499579600.dkr.ecr.us-east-1.amazonaws.com/techx-prod-corp/checkout:sha-fa6cb8f" in 1.223s (1.223s including waiting). Image size: 9514321 bytes.
14m         Normal    Pulling                pod/cart-6cbfb749cf-zw6b8                        Pulling image "493499579600.dkr.ecr.us-east-1.amazonaws.com/techx-prod-corp/cart:sha-fa6cb8f"
14m         Normal    Created                pod/cart-6cbfb749cf-zw6b8                        Container created
14m         Normal    Pulled                 pod/cart-6cbfb749cf-zw6b8                        Successfully pulled image "493499579600.dkr.ecr.us-east-1.amazonaws.com/techx-prod-corp/cart:sha-fa6cb8f" in 1.611s (1.611s including waiting). Image size: 50820594 bytes.
14m         Normal    Started                pod/cart-6cbfb749cf-zw6b8                        Container started
14m         Warning   Unhealthy              pod/cart-6cbfb749cf-zw6b8                        Readiness probe failed: timeout: failed to connect service "10.0.28.226:8080" within 3s: context deadline exceeded
14m         Normal    Pulled                 pod/frontend-75c8585d46-czn5b                    Successfully pulled image "493499579600.dkr.ecr.us-east-1.amazonaws.com/techx-prod-corp/frontend:sha-fa6cb8f" in 8.735s (8.735s including waiting). Image size: 213499853 bytes.
14m         Normal    Created                pod/frontend-75c8585d46-czn5b                    Container created
14m         Normal    Started                pod/frontend-75c8585d46-czn5b                    Container started
14m         Warning   Unhealthy              pod/frontend-75c8585d46-czn5b                    Readiness probe failed: Get "http://10.0.29.51:8080/": dial tcp 10.0.29.51:8080: connect: connection refused
14m         Warning   Unhealthy              pod/cart-6cbfb749cf-ncznm                        Readiness probe failed: timeout: failed to connect service "10.0.26.164:8080" within 3s: context deadline exceeded
14m         Warning   Unhealthy              pod/frontend-75c8585d46-f4jh8                    Readiness probe failed: Get "http://10.0.26.162:8080/": dial tcp 10.0.26.162:8080: connect: connection refused
14m         Normal    Evicted                pod/otel-collector-agent-qwlh9                   Evicted pod: Underutilized
14m         Normal    Killing                pod/otel-collector-agent-qwlh9                   Stopping container opentelemetry-collector
13m         Normal    Nominated              pod/cart-6cbfb749cf-npfkp                        Pod should schedule on: nodeclaim/stateless-spot-qczh4, node/ip-10-0-46-196.ec2.internal
13m         Normal    Scheduled              pod/otel-collector-agent-gbrl2                   Successfully assigned techx-corp-prod/otel-collector-agent-gbrl2 to ip-10-0-46-196.ec2.internal
13m         Normal    Pulling                pod/otel-collector-agent-gbrl2                   Pulling image "otel/opentelemetry-collector-contrib:0.151.0"
13m         Normal    Scheduled              pod/cart-6cbfb749cf-5mp2t                        Successfully assigned techx-corp-prod/cart-6cbfb749cf-5mp2t to ip-10-0-46-196.ec2.internal
13m         Normal    Evicted                pod/cart-6cbfb749cf-npfkp                        Evicted pod: Underutilized
13m         Normal    Killing                pod/cart-6cbfb749cf-npfkp                        Stopping container cart
13m         Normal    Pulling                pod/cart-6cbfb749cf-5mp2t                        Pulling image "busybox:1.37.0"
13m         Normal    Pulled                 pod/otel-collector-agent-gbrl2                   Successfully pulled image "otel/opentelemetry-collector-contrib:0.151.0" in 4.583s (4.583s including waiting). Image size: 88803327 bytes.
13m         Normal    Started                pod/otel-collector-agent-gbrl2                   Container started
13m         Normal    Created                pod/otel-collector-agent-gbrl2                   Container created
13m         Normal    Pulled                 pod/cart-6cbfb749cf-5mp2t                        Successfully pulled image "busybox:1.37.0" in 1.66s (1.66s including waiting). Image size: 1911349 bytes.
13m         Normal    Started                pod/cart-6cbfb749cf-5mp2t                        Container started
13m         Normal    Created                pod/cart-6cbfb749cf-5mp2t                        Container created
13m         Normal    SuccessfulCreate       cronjob/runtime-hardening-inventory              Created job runtime-hardening-inventory-29742125
13m         Normal    SuccessfulCreate       job/runtime-hardening-inventory-29742125         Created pod: runtime-hardening-inventory-29742125-fdwhw
13m         Normal    Pulled                 pod/runtime-hardening-inventory-29742125-fdwhw   Container image "public.ecr.aws/docker/library/python:3.13.5-alpine3.22" already present on machine and can be accessed by the pod
13m         Normal    Scheduled              pod/runtime-hardening-inventory-29742125-fdwhw   Successfully assigned techx-corp-prod/runtime-hardening-inventory-29742125-fdwhw to ip-10-0-36-4.ec2.internal
13m         Normal    Started                pod/runtime-hardening-inventory-29742125-fdwhw   Container started
13m         Normal    Created                pod/runtime-hardening-inventory-29742125-fdwhw   Container created
13m         Normal    Pulling                pod/cart-6cbfb749cf-5mp2t                        Pulling image "493499579600.dkr.ecr.us-east-1.amazonaws.com/techx-prod-corp/cart:sha-fa6cb8f"
13m         Normal    Created                pod/cart-6cbfb749cf-5mp2t                        Container created
13m         Normal    Pulled                 pod/cart-6cbfb749cf-5mp2t                        Successfully pulled image "493499579600.dkr.ecr.us-east-1.amazonaws.com/techx-prod-corp/cart:sha-fa6cb8f" in 1.675s (1.675s including waiting). Image size: 50820594 bytes.
13m         Normal    Started                pod/cart-6cbfb749cf-5mp2t                        Container started
13m         Warning   Unhealthy              pod/cart-6cbfb749cf-5mp2t                        Readiness probe failed: timeout: failed to connect service "10.0.46.128:8080" within 3s: context deadline exceeded
13m         Normal    Evicted                pod/otel-collector-agent-vpwm5                   Evicted pod: Underutilized
13m         Normal    Killing                pod/otel-collector-agent-vpwm5                   Stopping container opentelemetry-collector
13m         Warning   BackoffLimitExceeded   job/runtime-hardening-inventory-29742125         Job has reached the specified backoff limit
13m         Normal    SuccessfulDelete       cronjob/runtime-hardening-inventory              Deleted job runtime-hardening-inventory-29742110
13m         Normal    SawCompletedJob        cronjob/runtime-hardening-inventory              Saw completed job: runtime-hardening-inventory-29742125, condition: Failed
12m         Normal    Nominated              pod/cart-6cbfb749cf-6pg6k                        Pod should schedule on: nodeclaim/stateless-spot-4wbxg
12m         Normal    Scheduled              pod/otel-collector-agent-mrq2n                   Successfully assigned techx-corp-prod/otel-collector-agent-mrq2n to ip-10-0-17-16.ec2.internal
12m         Normal    Pulling                pod/otel-collector-agent-mrq2n                   Pulling image "otel/opentelemetry-collector-contrib:0.151.0"
12m         Normal    Scheduled              pod/cart-6cbfb749cf-m78fp                        Successfully assigned techx-corp-prod/cart-6cbfb749cf-m78fp to ip-10-0-17-16.ec2.internal
12m         Normal    Killing                pod/cart-6cbfb749cf-6pg6k                        Stopping container cart
12m         Normal    Evicted                pod/cart-6cbfb749cf-6pg6k                        Evicted pod: Underutilized
12m         Normal    Pulling                pod/cart-6cbfb749cf-m78fp                        Pulling image "busybox:1.37.0"
12m         Normal    Pulled                 pod/cart-6cbfb749cf-m78fp                        Successfully pulled image "busybox:1.37.0" in 690ms (690ms including waiting). Image size: 1911349 bytes.
12m         Normal    Created                pod/cart-6cbfb749cf-m78fp                        Container created
12m         Normal    Started                pod/cart-6cbfb749cf-m78fp                        Container started
12m         Normal    Created                pod/otel-collector-agent-mrq2n                   Container created
12m         Normal    Pulled                 pod/otel-collector-agent-mrq2n                   Successfully pulled image "otel/opentelemetry-collector-contrib:0.151.0" in 5.492s (5.492s including waiting). Image size: 88803327 bytes.
12m         Normal    Started                pod/otel-collector-agent-mrq2n                   Container started
12m         Normal    Pulling                pod/cart-6cbfb749cf-m78fp                        Pulling image "493499579600.dkr.ecr.us-east-1.amazonaws.com/techx-prod-corp/cart:sha-fa6cb8f"
12m         Normal    Pulled                 pod/cart-6cbfb749cf-m78fp                        Successfully pulled image "493499579600.dkr.ecr.us-east-1.amazonaws.com/techx-prod-corp/cart:sha-fa6cb8f" in 1.925s (1.925s including waiting). Image size: 50820594 bytes.
12m         Normal    Created                pod/cart-6cbfb749cf-m78fp                        Container created
12m         Normal    Started                pod/cart-6cbfb749cf-m78fp                        Container started
12m         Normal    Killing                pod/otel-collector-agent-97kvz                   Stopping container opentelemetry-collector
12m         Normal    Evicted                pod/otel-collector-agent-97kvz                   Evicted pod: Underutilized
12m         Warning   Unhealthy              pod/cart-6cbfb749cf-m78fp                        Readiness probe failed: timeout: failed to connect service "10.0.28.34:8080" within 3s: context deadline exceeded
12m         Warning   Unhealthy              pod/cart-6cbfb749cf-m78fp                        Readiness probe failed: timeout: health rpc did not complete within 3s
10m         Normal    SuccessfulDelete       replicaset/checkout-5f59884d8                    Deleted pod: checkout-5f59884d8-rnb5m
10m         Normal    ScalingReplicaSet      deployment/checkout                              Scaled down replica set checkout-5f59884d8 from 6 to 5
10m         Normal    SuccessfulRescale      horizontalpodautoscaler/checkout                 New size: 5; reason: All metrics below target
10m         Normal    Killing                pod/checkout-5f59884d8-rnb5m                     Stopping container checkout
10m         Normal    Killing                pod/cart-6cbfb749cf-m78fp                        Stopping container cart
10m         Normal    SuccessfulDelete       replicaset/cart-6cbfb749cf                       Deleted pod: cart-6cbfb749cf-m78fp
10m         Normal    SuccessfulDelete       replicaset/cart-6cbfb749cf                       Deleted pod: cart-6cbfb749cf-5mp2t
10m         Normal    Killing                pod/cart-6cbfb749cf-5mp2t                        Stopping container cart
10m         Normal    SuccessfulDelete       replicaset/cart-6cbfb749cf                       Deleted pod: cart-6cbfb749cf-7xl4m
10m         Normal    Killing                pod/cart-6cbfb749cf-7xl4m                        Stopping container cart
10m         Normal    SuccessfulRescale      horizontalpodautoscaler/cart                     New size: 8; reason: All metrics below target
10m         Normal    ScalingReplicaSet      deployment/cart                                  Scaled down replica set cart-6cbfb749cf from 9 to 8
10m         Normal    Killing                pod/cart-6cbfb749cf-dwcvr                        Stopping container cart
10m         Normal    SuccessfulDelete       replicaset/cart-6cbfb749cf                       Deleted pod: cart-6cbfb749cf-dwcvr
10m         Normal    Killing                pod/cart-6cbfb749cf-mfk44                        Stopping container cart
10m         Normal    Evicted                pod/cart-6cbfb749cf-mfk44                        Evicted pod: Underutilized
10m         Normal    Scheduled              pod/cart-6cbfb749cf-n6j6n                        Successfully assigned techx-corp-prod/cart-6cbfb749cf-n6j6n to ip-10-0-38-109.ec2.internal
10m         Normal    Nominated              pod/cart-6cbfb749cf-mfk44                        Pod should schedule on: nodeclaim/stateless-spot-4wbxg, node/ip-10-0-17-16.ec2.internal
10m         Normal    Pulled                 pod/cart-6cbfb749cf-n6j6n                        Successfully pulled image "busybox:1.37.0" in 131ms (131ms including waiting). Image size: 1911349 bytes.
10m         Normal    Created                pod/cart-6cbfb749cf-n6j6n                        Container created
10m         Normal    Pulling                pod/cart-6cbfb749cf-n6j6n                        Pulling image "busybox:1.37.0"
10m         Normal    Started                pod/cart-6cbfb749cf-n6j6n                        Container started
10m         Normal    Started                pod/cart-6cbfb749cf-n6j6n                        Container started
10m         Normal    Created                pod/cart-6cbfb749cf-n6j6n                        Container created
10m         Normal    Pulled                 pod/cart-6cbfb749cf-n6j6n                        Container image "493499579600.dkr.ecr.us-east-1.amazonaws.com/techx-prod-corp/cart:sha-fa6cb8f" already present on machine and can be accessed by the pod
10m         Warning   Unhealthy              pod/cart-6cbfb749cf-n6j6n                        Readiness probe failed: timeout: failed to connect service "10.0.44.83:8080" within 3s: context deadline exceeded
10m         Normal    Evicted                pod/otel-collector-agent-4slsx                   Evicted pod: Underutilized
10m         Normal    Killing                pod/otel-collector-agent-4slsx                   Stopping container opentelemetry-collector
9m47s       Normal    Nominated              pod/cart-6cbfb749cf-zw6b8                        Pod should schedule on: nodeclaim/stateless-spot-4wbxg, node/ip-10-0-17-16.ec2.internal
9m47s       Normal    Evicted                pod/cart-6cbfb749cf-zw6b8                        Evicted pod: Underutilized
9m47s       Normal    Killing                pod/cart-6cbfb749cf-zw6b8                        Stopping container cart
9m47s       Normal    Scheduled              pod/cart-6cbfb749cf-bzqkw                        Successfully assigned techx-corp-prod/cart-6cbfb749cf-bzqkw to ip-10-0-17-84.ec2.internal
9m46s       Normal    Pulled                 pod/cart-6cbfb749cf-bzqkw                        Successfully pulled image "busybox:1.37.0" in 148ms (148ms including waiting). Image size: 1911349 bytes.
9m46s       Normal    Created                pod/cart-6cbfb749cf-bzqkw                        Container created
9m46s       Normal    Started                pod/cart-6cbfb749cf-bzqkw                        Container started
9m46s       Normal    Pulling                pod/cart-6cbfb749cf-bzqkw                        Pulling image "busybox:1.37.0"
9m45s       Normal    Created                pod/cart-6cbfb749cf-bzqkw                        Container created
9m45s       Normal    Started                pod/cart-6cbfb749cf-bzqkw                        Container started
9m45s       Normal    Pulled                 pod/cart-6cbfb749cf-bzqkw                        Container image "493499579600.dkr.ecr.us-east-1.amazonaws.com/techx-prod-corp/cart:sha-fa6cb8f" already present on machine and can be accessed by the pod
9m36s       Normal    Evicted                pod/otel-collector-agent-4c4s8                   Evicted pod: Underutilized
9m36s       Normal    Killing                pod/otel-collector-agent-4c4s8                   Stopping container opentelemetry-collector
9m11s       Normal    Evicted                pod/otel-collector-agent-gbrl2                   Evicted pod: Empty
9m11s       Normal    Killing                pod/otel-collector-agent-gbrl2                   Stopping container opentelemetry-collector
9m8s        Normal    SuccessfulRescale      horizontalpodautoscaler/cart                     New size: 6; reason: All metrics below target
9m7s        Normal    Killing                pod/cart-6cbfb749cf-bzqkw                        Stopping container cart
9m7s        Normal    Killing                pod/cart-6cbfb749cf-n6j6n                        Stopping container cart
8m45s       Normal    Evicted                pod/otel-collector-agent-mrq2n                   Evicted pod: Empty
8m45s       Normal    Killing                pod/otel-collector-agent-mrq2n                   Stopping container opentelemetry-collector
8m36s       Normal    SuccessfulCreate       job/runtime-hardening-inventory-29742130         Created pod: runtime-hardening-inventory-29742130-5jlk5
8m36s       Normal    Pulled                 pod/runtime-hardening-inventory-29742130-5jlk5   Container image "public.ecr.aws/docker/library/python:3.13.5-alpine3.22" already present on machine and can be accessed by the pod
8m36s       Normal    Scheduled              pod/runtime-hardening-inventory-29742130-5jlk5   Successfully assigned techx-corp-prod/runtime-hardening-inventory-29742130-5jlk5 to ip-10-0-36-4.ec2.internal
8m36s       Normal    SuccessfulCreate       cronjob/runtime-hardening-inventory              Created job runtime-hardening-inventory-29742130
8m35s       Normal    Started                pod/runtime-hardening-inventory-29742130-5jlk5   Container started
8m35s       Normal    Created                pod/runtime-hardening-inventory-29742130-5jlk5   Container created
8m27s       Normal    SawCompletedJob        cronjob/runtime-hardening-inventory              Saw completed job: runtime-hardening-inventory-29742130, condition: Failed
8m27s       Normal    SuccessfulDelete       cronjob/runtime-hardening-inventory              Deleted job runtime-hardening-inventory-29742115
8m27s       Warning   BackoffLimitExceeded   job/runtime-hardening-inventory-29742130         Job has reached the specified backoff limit
8m19s       Normal    SuccessfulCreate       replicaset/frontend-75c8585d46                   Created pod: frontend-75c8585d46-tc7hz
8m19s       Normal    Evicted                pod/frontend-75c8585d46-czn5b                    Evicted pod: Underutilized
8m19s       Normal    Evicted                pod/cart-6cbfb749cf-lprsl                        Evicted pod: Underutilized
8m19s       Normal    Nominated              pod/frontend-75c8585d46-czn5b                    Pod should schedule on: nodeclaim/stateless-spot-tj66x, node/ip-10-0-17-84.ec2.internal
8m19s       Normal    Nominated              pod/cart-6cbfb749cf-lprsl                        Pod should schedule on: nodeclaim/stateless-spot-tj66x, node/ip-10-0-17-84.ec2.internal
8m19s       Normal    Scheduled              pod/frontend-75c8585d46-tc7hz                    Successfully assigned techx-corp-prod/frontend-75c8585d46-tc7hz to ip-10-0-17-84.ec2.internal
8m19s       Normal    Killing                pod/cart-6cbfb749cf-lprsl                        Stopping container cart
8m19s       Normal    Scheduled              pod/cart-6cbfb749cf-hz49n                        Successfully assigned techx-corp-prod/cart-6cbfb749cf-hz49n to ip-10-0-17-84.ec2.internal
8m19s       Normal    Killing                pod/frontend-75c8585d46-czn5b                    Stopping container frontend
8m18s       Normal    Created                pod/cart-6cbfb749cf-hz49n                        Container created
8m18s       Normal    Pulling                pod/frontend-75c8585d46-tc7hz                    Pulling image "493499579600.dkr.ecr.us-east-1.amazonaws.com/techx-prod-corp/frontend:sha-fa6cb8f"
8m18s       Normal    Pulled                 pod/cart-6cbfb749cf-hz49n                        Successfully pulled image "busybox:1.37.0" in 132ms (132ms including waiting). Image size: 1911349 bytes.
8m18s       Normal    Pulling                pod/cart-6cbfb749cf-hz49n                        Pulling image "busybox:1.37.0"
8m18s       Normal    Started                pod/cart-6cbfb749cf-hz49n                        Container started
8m17s       Normal    Started                pod/cart-6cbfb749cf-hz49n                        Container started
8m17s       Normal    Pulled                 pod/cart-6cbfb749cf-hz49n                        Container image "493499579600.dkr.ecr.us-east-1.amazonaws.com/techx-prod-corp/cart:sha-fa6cb8f" already present on machine and can be accessed by the pod
8m17s       Normal    Created                pod/cart-6cbfb749cf-hz49n                        Container created
8m14s       Warning   Unhealthy              pod/cart-6cbfb749cf-hz49n                        Readiness probe failed: timeout: failed to connect service "10.0.19.179:8080" within 3s: context deadline exceeded
8m11s       Warning   Unhealthy              pod/cart-6cbfb749cf-hz49n                        Readiness probe failed: timeout: health rpc did not complete within 3s
8m10s       Normal    Created                pod/frontend-75c8585d46-tc7hz                    Container created
8m10s       Normal    Pulled                 pod/frontend-75c8585d46-tc7hz                    Successfully pulled image "493499579600.dkr.ecr.us-east-1.amazonaws.com/techx-prod-corp/frontend:sha-fa6cb8f" in 8.659s (8.659s including waiting). Image size: 213499853 bytes.
8m9s        Normal    Started                pod/frontend-75c8585d46-tc7hz                    Container started
8m8s        Warning   Unhealthy              pod/frontend-75c8585d46-tc7hz                    Readiness probe failed: Get "http://10.0.19.176:8080/": dial tcp 10.0.19.176:8080: connect: connection refused
8m7s        Normal    Killing                pod/cart-6cbfb749cf-hz49n                        Stopping container cart
8m7s        Normal    Evicted                pod/otel-collector-agent-2qtfd                   Evicted pod: Underutilized
8m7s        Normal    Killing                pod/otel-collector-agent-2qtfd                   Stopping container opentelemetry-collector
8m6s        Warning   Unhealthy              pod/otel-collector-agent-2qtfd                   Readiness probe failed: Get "http://10.0.29.49:13133/": dial tcp 10.0.29.49:13133: connect: connection refused
8m5s        Warning   Unhealthy              pod/cart-6cbfb749cf-lprsl                        Readiness probe failed: timeout: failed to connect service "10.0.29.48:8080" within 3s: context deadline exceeded
7m42s       Normal    Evicted                pod/product-reviews-58686f5fd9-qs6jg             Evicted pod: Underutilized
7m42s       Normal    Killing                pod/checkout-5f59884d8-8gpz8                     Stopping container checkout
7m42s       Normal    Evicted                pod/cart-6cbfb749cf-zghqz                        Evicted pod: Underutilized
7m42s       Normal    Killing                pod/cart-6cbfb749cf-zghqz                        Stopping container cart
7m42s       Normal    Nominated              pod/cart-6cbfb749cf-zghqz                        Pod should schedule on: nodeclaim/stateless-spot-tj66x, node/ip-10-0-17-84.ec2.internal
7m42s       Normal    Scheduled              pod/cart-6cbfb749cf-h4dbf                        Successfully assigned techx-corp-prod/cart-6cbfb749cf-h4dbf to ip-10-0-38-109.ec2.internal
7m42s       Normal    Scheduled              pod/checkout-5f59884d8-xn9jj                     Successfully assigned techx-corp-prod/checkout-5f59884d8-xn9jj to ip-10-0-17-84.ec2.internal
7m42s       Normal    SuccessfulCreate       replicaset/product-reviews-58686f5fd9            Created pod: product-reviews-58686f5fd9-p8snq
7m42s       Normal    Killing                pod/product-reviews-58686f5fd9-qs6jg             Stopping container product-reviews
7m42s       Normal    Scheduled              pod/product-reviews-58686f5fd9-p8snq             Successfully assigned techx-corp-prod/product-reviews-58686f5fd9-p8snq to ip-10-0-38-109.ec2.internal
7m42s       Normal    Nominated              pod/checkout-5f59884d8-8gpz8                     Pod should schedule on: nodeclaim/stateless-spot-tj66x, node/ip-10-0-17-84.ec2.internal
7m42s       Normal    Evicted                pod/checkout-5f59884d8-8gpz8                     Evicted pod: Underutilized
7m42s       Normal    Pulling                pod/cart-6cbfb749cf-h4dbf                        Pulling image "busybox:1.37.0"
7m42s       Normal    Nominated              pod/product-reviews-58686f5fd9-qs6jg             Pod should schedule on: nodeclaim/stateless-spot-bwp68, node/ip-10-0-36-190.ec2.internal
7m42s       Normal    SuccessfulCreate       replicaset/checkout-5f59884d8                    Created pod: checkout-5f59884d8-xn9jj
7m41s       Normal    Started                pod/checkout-5f59884d8-xn9jj                     Container started
7m41s       Normal    Pulled                 pod/cart-6cbfb749cf-h4dbf                        Container image "493499579600.dkr.ecr.us-east-1.amazonaws.com/techx-prod-corp/cart:sha-fa6cb8f" already present on machine and can be accessed by the pod
7m41s       Normal    Created                pod/checkout-5f59884d8-xn9jj                     Container created
7m41s       Normal    Pulling                pod/product-reviews-58686f5fd9-p8snq             Pulling image "public.ecr.aws/aws-cli/aws-cli:2.27.49"
7m41s       Normal    Started                pod/cart-6cbfb749cf-h4dbf                        Container started
7m41s       Normal    Created                pod/cart-6cbfb749cf-h4dbf                        Container created
7m41s       Normal    Pulled                 pod/cart-6cbfb749cf-h4dbf                        Successfully pulled image "busybox:1.37.0" in 136ms (136ms including waiting). Image size: 1911349 bytes.
7m41s       Normal    Pulled                 pod/checkout-5f59884d8-xn9jj                     Container image "493499579600.dkr.ecr.us-east-1.amazonaws.com/techx-prod-corp/checkout:sha-fa6cb8f" already present on machine and can be accessed by the pod
7m40s       Normal    Created                pod/cart-6cbfb749cf-h4dbf                        Container created
7m40s       Normal    Started                pod/cart-6cbfb749cf-h4dbf                        Container started
7m37s       Warning   Unhealthy              pod/cart-6cbfb749cf-h4dbf                        Readiness probe failed: timeout: failed to connect service "10.0.44.83:8080" within 3s: context deadline exceeded
7m37s       Normal    Pulled                 pod/product-reviews-58686f5fd9-p8snq             Successfully pulled image "public.ecr.aws/aws-cli/aws-cli:2.27.49" in 4.717s (4.717s including waiting). Image size: 130951142 bytes.
7m37s       Normal    Created                pod/product-reviews-58686f5fd9-p8snq             Container created
7m37s       Normal    Started                pod/product-reviews-58686f5fd9-p8snq             Container started
7m11s       Normal    Pulled                 pod/product-reviews-58686f5fd9-p8snq             Container image "busybox:1.37.0" already present on machine and can be accessed by the pod
7m11s       Normal    Started                pod/product-reviews-58686f5fd9-p8snq             Container started
7m11s       Normal    Killing                pod/otel-collector-agent-nrrj7                   Stopping container opentelemetry-collector
7m11s       Normal    Evicted                pod/otel-collector-agent-nrrj7                   Evicted pod: Underutilized
7m11s       Normal    Created                pod/product-reviews-58686f5fd9-p8snq             Container created
6m45s       Normal    Nominated              pod/cart-6cbfb749cf-d8mm5                        Pod should schedule on: nodeclaim/stateless-spot-tj66x, node/ip-10-0-17-84.ec2.internal
6m45s       Normal    Scheduled              pod/cart-6cbfb749cf-4wr9p                        Successfully assigned techx-corp-prod/cart-6cbfb749cf-4wr9p to ip-10-0-17-84.ec2.internal
6m45s       Normal    Nominated              pod/checkout-5f59884d8-69fnj                     Pod should schedule on: nodeclaim/stateless-spot-rgggn, node/ip-10-0-38-109.ec2.internal
6m45s       Normal    Killing                pod/checkout-5f59884d8-69fnj                     Stopping container checkout
6m45s       Normal    Evicted                pod/checkout-5f59884d8-69fnj                     Evicted pod: Underutilized
6m45s       Normal    Scheduled              pod/checkout-5f59884d8-6dch5                     Successfully assigned techx-corp-prod/checkout-5f59884d8-6dch5 to ip-10-0-38-109.ec2.internal
6m45s       Normal    Pulling                pod/checkout-5f59884d8-6dch5                     Pulling image "493499579600.dkr.ecr.us-east-1.amazonaws.com/techx-prod-corp/checkout:sha-fa6cb8f"
6m45s       Normal    SuccessfulCreate       replicaset/checkout-5f59884d8                    Created pod: checkout-5f59884d8-6dch5
6m45s       Normal    Killing                pod/cart-6cbfb749cf-d8mm5                        Stopping container cart
6m45s       Normal    Evicted                pod/cart-6cbfb749cf-d8mm5                        Evicted pod: Underutilized
6m45s       Normal    Nominated              pod/accounting-69d676466f-6jtpf                  Pod should schedule on: nodeclaim/stateless-spot-tj66x, node/ip-10-0-17-84.ec2.internal
6m45s       Normal    SuccessfulCreate       replicaset/accounting-69d676466f                 Created pod: accounting-69d676466f-vzjgh
6m45s       Normal    Scheduled              pod/accounting-69d676466f-vzjgh                  Successfully assigned techx-corp-prod/accounting-69d676466f-vzjgh to ip-10-0-17-84.ec2.internal
6m45s       Normal    Killing                pod/accounting-69d676466f-6jtpf                  Stopping container accounting
6m45s       Normal    Evicted                pod/accounting-69d676466f-6jtpf                  Evicted pod: Underutilized
6m44s       Normal    Started                pod/cart-6cbfb749cf-4wr9p                        Container started
6m44s       Normal    Pulled                 pod/cart-6cbfb749cf-4wr9p                        Container image "493499579600.dkr.ecr.us-east-1.amazonaws.com/techx-prod-corp/cart:sha-fa6cb8f" already present on machine and can be accessed by the pod
6m44s       Normal    Created                pod/cart-6cbfb749cf-4wr9p                        Container created
6m44s       Normal    Pulled                 pod/cart-6cbfb749cf-4wr9p                        Successfully pulled image "busybox:1.37.0" in 143ms (143ms including waiting). Image size: 1911349 bytes.
6m44s       Normal    Pulling                pod/cart-6cbfb749cf-4wr9p                        Pulling image "busybox:1.37.0"
6m44s       Normal    Pulling                pod/accounting-69d676466f-vzjgh                  Pulling image "493499579600.dkr.ecr.us-east-1.amazonaws.com/techx-prod-corp/accounting:sha-fa6cb8f"
6m44s       Normal    Started                pod/cart-6cbfb749cf-4wr9p                        Container started
6m44s       Normal    Created                pod/cart-6cbfb749cf-4wr9p                        Container created
6m43s       Normal    Created                pod/checkout-5f59884d8-6dch5                     Container created
6m43s       Normal    Started                pod/checkout-5f59884d8-6dch5                     Container started
6m43s       Normal    Pulled                 pod/checkout-5f59884d8-6dch5                     Successfully pulled image "493499579600.dkr.ecr.us-east-1.amazonaws.com/techx-prod-corp/checkout:sha-fa6cb8f" in 1.152s (1.152s including waiting). Image size: 9514321 bytes.
6m41s       Warning   Unhealthy              pod/cart-6cbfb749cf-4wr9p                        Readiness probe failed: timeout: failed to connect service "10.0.19.179:8080" within 3s: context deadline exceeded
6m40s       Normal    Started                pod/accounting-69d676466f-vzjgh                  Container started
6m40s       Normal    Created                pod/accounting-69d676466f-vzjgh                  Container created
6m40s       Normal    Pulled                 pod/accounting-69d676466f-vzjgh                  Successfully pulled image "493499579600.dkr.ecr.us-east-1.amazonaws.com/techx-prod-corp/accounting:sha-fa6cb8f" in 4.06s (4.06s including waiting). Image size: 101851664 bytes.
6m38s       Warning   Unhealthy              pod/cart-6cbfb749cf-4wr9p                        Readiness probe failed: timeout: health rpc did not complete within 3s
6m34s       Normal    Killing                pod/otel-collector-agent-wbrhx                   Stopping container opentelemetry-collector
6m34s       Normal    Evicted                pod/otel-collector-agent-wbrhx                   Evicted pod: Underutilized
6m32s       Normal    Pulling                pod/product-reviews-58686f5fd9-p8snq             Pulling image "493499579600.dkr.ecr.us-east-1.amazonaws.com/techx-prod-corp/product-reviews:sha-fa6cb8f"
6m11s       Normal    Pulled                 pod/product-reviews-58686f5fd9-p8snq             Successfully pulled image "493499579600.dkr.ecr.us-east-1.amazonaws.com/techx-prod-corp/product-reviews:sha-fa6cb8f" in 21.119s (21.119s including waiting). Image size: 732871123 bytes.
6m10s       Normal    Started                pod/product-reviews-58686f5fd9-p8snq             Container started
6m10s       Normal    Created                pod/product-reviews-58686f5fd9-p8snq             Container created
5m57s       Warning   Unhealthy              pod/product-reviews-58686f5fd9-p8snq             Startup probe failed: timeout: failed to connect service "10.0.44.80:3551" within 5s: context deadline exceeded
5m52s       Warning   FailedScheduling       pod/cart-6cbfb749cf-ltdj5                        0/8 nodes are available: 1 node(s) didn't satisfy existing pods anti-affinity rules, 2 node(s) didn't match Pod's node affinity/selector, 5 node(s) didn't match pod topology spread constraints. no new claims to deallocate, preemption: 0/8 nodes are available: 2 Preemption is not helpful for scheduling, 6 No preemption victims found for incoming pod.
5m52s       Normal    ScalingReplicaSet      deployment/cart                                  (combined from similar events): Scaled up replica set cart-6cbfb749cf from 5 to 6
5m52s       Normal    SuccessfulRescale      horizontalpodautoscaler/cart                     (combined from similar events): New size: 6; reason: cpu resource utilization (percentage of request) above target
5m52s       Normal    SuccessfulCreate       replicaset/cart-6cbfb749cf                       (combined from similar events): Created pod: cart-6cbfb749cf-ltdj5
5m51s       Normal    Nominated              pod/cart-6cbfb749cf-ltdj5                        Pod should schedule on: nodeclaim/stateless-spot-j2gzp
5m48s       Normal    NotTriggerScaleUp      pod/cart-6cbfb749cf-ltdj5                        pod didn't trigger scale-up: 2 node(s) didn't match Pod's node affinity/selector
5m26s       Warning   FailedScheduling       pod/cart-6cbfb749cf-ltdj5                        0/9 nodes are available: 1 node(s) didn't satisfy existing pods anti-affinity rules, 1 node(s) had untolerated taint(s), 2 node(s) didn't match Pod's node affinity/selector, 5 node(s) didn't match pod topology spread constraints. no new claims to deallocate, preemption: 0/9 nodes are available: 3 Preemption is not helpful for scheduling, 6 No preemption victims found for incoming pod.
5m19s       Normal    Scheduled              pod/cart-6cbfb749cf-ltdj5                        Successfully assigned techx-corp-prod/cart-6cbfb749cf-ltdj5 to ip-10-0-29-241.ec2.internal
5m18s       Normal    SuccessfulCreate       daemonset/otel-collector-agent                   (combined from similar events): Created pod: otel-collector-agent-dh55r
5m18s       Normal    Scheduled              pod/otel-collector-agent-dh55r                   Successfully assigned techx-corp-prod/otel-collector-agent-dh55r to ip-10-0-29-241.ec2.internal
5m18s       Normal    Pulling                pod/otel-collector-agent-dh55r                   Pulling image "otel/opentelemetry-collector-contrib:0.151.0"
5m18s       Normal    Pulling                pod/cart-6cbfb749cf-ltdj5                        Pulling image "busybox:1.37.0"
5m17s       Normal    Started                pod/cart-6cbfb749cf-ltdj5                        Container started
5m17s       Normal    Created                pod/cart-6cbfb749cf-ltdj5                        Container created
5m17s       Normal    Pulled                 pod/cart-6cbfb749cf-ltdj5                        Successfully pulled image "busybox:1.37.0" in 576ms (576ms including waiting). Image size: 1911349 bytes.
5m16s       Normal    TaintManagerEviction   pod/cart-6cbfb749cf-ltdj5                        Cancelling deletion of Pod techx-corp-prod/cart-6cbfb749cf-ltdj5
5m14s       Normal    Pulling                pod/cart-6cbfb749cf-ltdj5                        Pulling image "493499579600.dkr.ecr.us-east-1.amazonaws.com/techx-prod-corp/cart:sha-fa6cb8f"
5m11s       Normal    Started                pod/cart-6cbfb749cf-ltdj5                        Container started
5m11s       Normal    Pulled                 pod/otel-collector-agent-dh55r                   Successfully pulled image "otel/opentelemetry-collector-contrib:0.151.0" in 6.223s (6.223s including waiting). Image size: 88803327 bytes.
5m11s       Normal    Created                pod/otel-collector-agent-dh55r                   Container created
5m11s       Normal    Started                pod/otel-collector-agent-dh55r                   Container started
5m11s       Normal    Pulled                 pod/cart-6cbfb749cf-ltdj5                        Successfully pulled image "493499579600.dkr.ecr.us-east-1.amazonaws.com/techx-prod-corp/cart:sha-fa6cb8f" in 2.906s (2.906s including waiting). Image size: 50820594 bytes.
5m11s       Normal    Created                pod/cart-6cbfb749cf-ltdj5                        Container created
5m8s        Warning   Unhealthy              pod/cart-6cbfb749cf-ltdj5                        Readiness probe failed: timeout: failed to connect service "10.0.28.144:8080" within 3s: context deadline exceeded
5m5s        Warning   Unhealthy              pod/cart-6cbfb749cf-ltdj5                        Readiness probe failed: timeout: health rpc did not complete within 3s
3m36s       Normal    SuccessfulCreate       cronjob/runtime-hardening-inventory              Created job runtime-hardening-inventory-29742135
3m36s       Normal    Scheduled              pod/runtime-hardening-inventory-29742135-cq649   Successfully assigned techx-corp-prod/runtime-hardening-inventory-29742135-cq649 to ip-10-0-36-4.ec2.internal
3m36s       Normal    SuccessfulCreate       job/runtime-hardening-inventory-29742135         Created pod: runtime-hardening-inventory-29742135-cq649
3m35s       Normal    Created                pod/runtime-hardening-inventory-29742135-cq649   Container created
3m35s       Normal    Started                pod/runtime-hardening-inventory-29742135-cq649   Container started
3m35s       Normal    Pulled                 pod/runtime-hardening-inventory-29742135-cq649   Container image "public.ecr.aws/docker/library/python:3.13.5-alpine3.22" already present on machine and can be accessed by the pod
3m27s       Normal    SuccessfulDelete       cronjob/runtime-hardening-inventory              Deleted job runtime-hardening-inventory-29742120
3m27s       Warning   BackoffLimitExceeded   job/runtime-hardening-inventory-29742135         Job has reached the specified backoff limit
3m27s       Normal    SawCompletedJob        cronjob/runtime-hardening-inventory              Saw completed job: runtime-hardening-inventory-29742135, condition: Failed
93s         Normal    SuccessfulDelete       replicaset/frontend-75c8585d46                   Deleted pod: frontend-75c8585d46-tc7hz
93s         Normal    ScalingReplicaSet      deployment/frontend                              Scaled down replica set frontend-75c8585d46 from 4 to 3
93s         Normal    Killing                pod/frontend-75c8585d46-tc7hz                    Stopping container frontend
93s         Normal    SuccessfulRescale      horizontalpodautoscaler/frontend                 New size: 3; reason: All metrics below target
37s         Normal    SuccessfulRescale      horizontalpodautoscaler/cart                     New size: 5; reason: All metrics below target
37s         Normal    SuccessfulDelete       replicaset/cart-6cbfb749cf                       (combined from similar events): Deleted pod: cart-6cbfb749cf-ltdj5
37s         Normal    Killing                pod/cart-6cbfb749cf-ltdj5                        Stopping container cart
37s         Normal    ScalingReplicaSet      deployment/cart                                  Scaled down replica set cart-6cbfb749cf from 6 to 5
9s          Normal    Nominated              pod/product-reviews-58686f5fd9-p8snq             Pod should schedule on: nodeclaim/stateless-spot-bwp68, node/ip-10-0-36-190.ec2.internal
9s          Normal    Evicted                pod/product-reviews-58686f5fd9-p8snq             Evicted pod: Underutilized
9s          Normal    Killing                pod/cart-6cbfb749cf-h4dbf                        Stopping container cart
9s          Normal    SuccessfulCreate       replicaset/checkout-5f59884d8                    (combined from similar events): Created pod: checkout-5f59884d8-qggnk
9s          Normal    Scheduled              pod/checkout-5f59884d8-qggnk                     Successfully assigned techx-corp-prod/checkout-5f59884d8-qggnk to ip-10-0-29-241.ec2.internal
9s          Normal    Nominated              pod/checkout-5f59884d8-6dch5                     Pod should schedule on: nodeclaim/stateless-spot-j2gzp, node/ip-10-0-29-241.ec2.internal
9s          Normal    Pulling                pod/checkout-5f59884d8-qggnk                     Pulling image "493499579600.dkr.ecr.us-east-1.amazonaws.com/techx-prod-corp/checkout:sha-fa6cb8f"
9s          Normal    Scheduled              pod/cart-6cbfb749cf-8mrrf                        Successfully assigned techx-corp-prod/cart-6cbfb749cf-8mrrf to ip-10-0-29-241.ec2.internal
9s          Normal    Nominated              pod/cart-6cbfb749cf-h4dbf                        Pod should schedule on: nodeclaim/stateless-spot-j2gzp, node/ip-10-0-29-241.ec2.internal
9s          Normal    Scheduled              pod/product-reviews-58686f5fd9-tzbcb             Successfully assigned techx-corp-prod/product-reviews-58686f5fd9-tzbcb to ip-10-0-40-214.ec2.internal
9s          Normal    Evicted                pod/checkout-5f59884d8-6dch5                     Evicted pod: Underutilized
9s          Normal    Killing                pod/checkout-5f59884d8-6dch5                     Stopping container checkout
9s          Normal    Pulling                pod/cart-6cbfb749cf-8mrrf                        Pulling image "busybox:1.37.0"
9s          Normal    Killing                pod/product-reviews-58686f5fd9-p8snq             Stopping container product-reviews
9s          Normal    SuccessfulCreate       replicaset/product-reviews-58686f5fd9            Created pod: product-reviews-58686f5fd9-tzbcb
9s          Normal    Evicted                pod/cart-6cbfb749cf-h4dbf                        Evicted pod: Underutilized
9s          Normal    Pulling                pod/product-reviews-58686f5fd9-tzbcb             Pulling image "public.ecr.aws/aws-cli/aws-cli:2.27.49"
8s          Normal    Started                pod/cart-6cbfb749cf-8mrrf                        Container started
8s          Normal    Pulled                 pod/cart-6cbfb749cf-8mrrf                        Container image "493499579600.dkr.ecr.us-east-1.amazonaws.com/techx-prod-corp/cart:sha-fa6cb8f" already present on machine and can be accessed by the pod
8s          Normal    Created                pod/cart-6cbfb749cf-8mrrf                        Container created
8s          Normal    Pulled                 pod/cart-6cbfb749cf-8mrrf                        Successfully pulled image "busybox:1.37.0" in 154ms (154ms including waiting). Image size: 1911349 bytes.
8s          Normal    Created                pod/cart-6cbfb749cf-8mrrf                        Container created
8s          Normal    Started                pod/cart-6cbfb749cf-8mrrf                        Container started
7s          Normal    Started                pod/checkout-5f59884d8-qggnk                     Container started
7s          Normal    Created                pod/checkout-5f59884d8-qggnk                     Container created
7s          Normal    Pulled                 pod/checkout-5f59884d8-qggnk                     Successfully pulled image "493499579600.dkr.ecr.us-east-1.amazonaws.com/techx-prod-corp/checkout:sha-fa6cb8f" in 1.323s (1.323s including waiting). Image size: 9514321 bytes.
5s          Warning   Unhealthy              pod/cart-6cbfb749cf-8mrrf                        Readiness probe failed: timeout: failed to connect service "10.0.28.147:8080" within 3s: context deadline exceeded
4s          Normal    Pulled                 pod/product-reviews-58686f5fd9-tzbcb             Successfully pulled image "public.ecr.aws/aws-cli/aws-cli:2.27.49" in 4.216s (4.216s including waiting). Image size: 130951142 bytes.
4s          Normal    Created                pod/product-reviews-58686f5fd9-tzbcb             Container created
4s          Normal    Started                pod/product-reviews-58686f5fd9-tzbcb             Container started
2s          Warning   Unhealthy              pod/cart-6cbfb749cf-8mrrf                        Readiness probe failed: timeout: health rpc did not complete within 3s
